Workbook

Sheet Paper_1
A1: Asset | B1: Threat type | C1: Security Attribute | D1: Damage Scenario | E1: Attack Path | F1: Attack vector | G1: Attack Vector Note / Motiv | H1: Safety Impact | I1: Safety Note / Motiv | J1: Financial Impact | K1: Financial Note / Motiv | L1: Operational Impact | M1: Operational Note / Motiv | N1: Privacy and Legislative Impact | O1: Privacy Note / Motiv | P1: Severity Level | Q1: Feasibility Level | R1: Risk Value | S1: Treatment Options | T1: Measures | U1: Affected Design Elements | V1: Justification (Treatment) | W1: Cybersecurity Goals | Y1: s | Z1: f | AA1: o | AB1: p | AC1: impact | AD1: feasibility val | AE1: Risk score
A2: DENM Management Container- StationType | B2: Tampering | C2: Integrity | D2: The sender changes the StationType between two consecutive DENMs. | E2: The attacker needs access to a legitimate or compromised OBU (On-Board Unit) in the vehicle. | F2: Network | G2: This attack involves manipulating the message content (StationType) within the communication network. | H2: Negligible | I2: No immediate safety impact, but misclassification may affect priority-based decision-making. | J2: Moderate | K2: The impact is minimal and does not lead to substantial losses or any financial threat to the organization. | L2: Moderate | M2: It could cause minor disruption or annoyance if the wrong vehicle type is displayed, but it does not affect core functions. | N2: Negligible | O2: Changing the StationType in a DENM does not involve any privacy-sensitive data (e.g., driver or vehicle-specific information) nor does it directly violate legislation. | P2: =IF(AC2>=Reference!$H$2, Reference!$G$2, IF(AC2>=Reference!$H$3, Reference!$G$3, IF(AC2>=Reference!$H$4, Reference!$G$4, IF(AC2>=Reference!$H$5, Reference!$G$5, "")))) -> Moderate | Q2: =IF(F2="Physical", "Very Low", IF(F2="Local", "Low", IF(F2="Adjacent", "Medium", IF(F2="Network", "High", "")))) -> High | R2: =IF(AE2>=Reference!$D$2, Reference!$G$2, IF(AE2>=Reference!$D$3, Reference!$E$3, IF(AE2>=Reference!$D$4, Reference!$E$4, IF(AE2>=Reference!$D$5, Reference!$E$5, "")))) -> Medium | S2: Mitigation | T2: CAM message verification, Digital Signatures, Anomaly Detection, Rate Limiting, Trust-Based Filtering | U2: Authentication (PKI, Certificates), Message Parsing, Trust Management, CAM Validation, Security Policies, Autonomous Decision-Making | V2: Low impact but needs cryptographic checks and cross-verification with CAM messages. | Y2: =IF(H2=Reference!$A$12, Reference!$C$12, IF(H2=Reference!$A$11, Reference!$C$11, IF(H2=Reference!$A$10, Reference!$C$10, IF(H2=Reference!$A$9, Reference!$C$9, 0)))) -> 1 | Z2: =IF(J2=Reference!$A$20, Reference!$C$20, IF(J2=Reference!$A$19, Reference!$C$19, IF(J2=Reference!$A$18, Reference!$C$18, IF(J2=Reference!$A$17, Reference!$C$17, 0)))) -> 4 | AA2: =IF(L2=Reference!$A$28, Reference!$C$28, IF(L2=Reference!$A$27, Reference!$C$27, IF(L2=Reference!$A$26, Reference!$C$26, IF(L2=Reference!$A$25, Reference!$C$25, 0)))) -> 4 | AB2: =IF(N2=Reference!$A$36, Reference!$C$36, IF(N2=Reference!$A$35, Reference!$C$35, IF(N2=Reference!$A$34, Reference!$C$34, IF(N2=Reference!$A$33, Reference!$C$33, 0)))) -> 1 | AC2: =(Reference!$B$2*Y2 + Reference!$B$3*AA2 + Reference!$B$4*Z2 + Reference!$B$5 * AB2)/4 -> 2.8125 | AD2: =IF(Q2=Reference!$C$41, Reference!$D$41, IF(Q2=Reference!$C$42, Reference!$D$42, IF(Q2=Reference!$C$43, Reference!$D$43, IF(Q2=Reference!$C$44, Reference!$D$44, 0)))) -> 10 | AE2: =1 + (AC2 * AD2) -> 29.125
B3: Spoofing | C3: Integrity | D3: The attacker alters the StationType field to falsely represent a roadside unit (RSU) as a vehicle or vice versa, misleading receiving ITS stations about the event source. | E3: Attacker gains network access to the vehicle or RSU communication module to manipulate the StationType field before DENM is broadcasted. | F3: Network | G3: The attacker intends to cause confusion or degrade trust in communication by falsifying the origin of hazard information. | H3: Moderate | I3: Misinformation regarding the station type could cause moderate confusion among drivers, reducing effective responses to hazards. | J3: Moderate | K3: Financial damage is minimal, mainly associated with operational inefficiencies and minor reputational concerns manageable by the organization. | L3: Moderate | M3: Operational inefficiencies due to misallocated attention or minor rerouting resulting from incorrect station type identification. | N3: Moderate | O3: Minimal legislative concerns, no significant privacy violations as StationType does not directly involve sensitive user data. | P3: =IF(AC3>=Reference!$H$2, Reference!$G$2, IF(AC3>=Reference!$H$3, Reference!$G$3, IF(AC3>=Reference!$H$4, Reference!$G$4, IF(AC3>=Reference!$H$5, Reference!$G$5, "")))) -> Major | Q3: =IF(F3="Physical", "Very Low", IF(F3="Local", "Low", IF(F3="Adjacent", "Medium", IF(F3="Network", "High", "")))) -> High | R3: =IF(AE3>=Reference!$D$2, Reference!$G$2, IF(AE3>=Reference!$D$3, Reference!$E$3, IF(AE3>=Reference!$D$4, Reference!$E$4, IF(AE3>=Reference!$D$5, Reference!$E$5, "")))) -> High | S3: Mitigation | T3: Cryptographic authentication and integrity checks on DENM messages.Station type verification protocols to validate incoming message authenticity.Anomaly detection systems monitoring unusual patterns of station type reporting. | U3: OBU and RSU message authentication modules.Backend validation systems for StationType verification.Monitoring and logging mechanisms. | V3: Accurate identification of message origin is critical for maintaining operational efficiency, hazard response reliability, and trustworthiness of the V2X communication system. | W3: Integrity, Authenticity, Non-repudiation. | Y3: =IF(H3=Reference!$A$12, Reference!$C$12, IF(H3=Reference!$A$11, Reference!$C$11, IF(H3=Reference!$A$10, Reference!$C$10, IF(H3=Reference!$A$9, Reference!$C$9, 0)))) -> 4 | Z3: =IF(J3=Reference!$A$20, Reference!$C$20, IF(J3=Reference!$A$19, Reference!$C$19, IF(J3=Reference!$A$18, Reference!$C$18, IF(J3=Reference!$A$17, Reference!$C$17, 0)))) -> 4 | AA3: =IF(L3=Reference!$A$28, Reference!$C$28, IF(L3=Reference!$A$27, Reference!$C$27, IF(L3=Reference!$A$26, Reference!$C$26, IF(L3=Reference!$A$25, Reference!$C$25, 0)))) -> 4 | AB3: =IF(N3=Reference!$A$36, Reference!$C$36, IF(N3=Reference!$A$35, Reference!$C$35, IF(N3=Reference!$A$34, Reference!$C$34, IF(N3=Reference!$A$33, Reference!$C$33, 0)))) -> 4 | AC3: =(Reference!$B$2*Y3 + Reference!$B$3*AA3 + Reference!$B$4*Z3 + Reference!$B$5 * AB3)/4 -> 6.75 | AD3: =IF(Q3=Reference!$C$41, Reference!$D$41, IF(Q3=Reference!$C$42, Reference!$D$42, IF(Q3=Reference!$C$43, Reference!$D$43, IF(Q3=Reference!$C$44, Reference!$D$44, 0)))) -> 10 | AE3: =1 + (AC3 * AD3) -> 68.5
B4: Information disclosure | C4: Confidentiality | D4: An attacker modifies the StationType to falsely identify a regular vehicle or RSU as an emergency vehicle (e.g., ambulance, police car), resulting in incorrect prioritization or response by other vehicles and infrastructure. | E4: Attacker remotely compromises vehicle or RSU communications to inject altered StationType value indicating an emergency vehicle. | F4: Network | G4: Attacker aims to disrupt traffic flow, obtain illegitimate traffic priority, or cause emergency response confusion. | H4: Major | I4: False emergency notifications may lead to sudden braking, confusion, or increased collision risks, potentially resulting in severe injuries. | J4: Major | K4: Substantial financial implications due to liability from potential accidents, significant reputational damage, and increased insurance premiums for stakeholders. | L4: Major | M4: Major operational disruption caused by unnecessary yielding, incorrect rerouting, and reduced efficiency of emergency response services. | N4: Major | O4: Unauthorized alteration of StationType, especially impersonating an emergency or special-purpose vehicle, is a serious privacy and confidentiality breach. This could lead to legal consequences, regulatory actions, and potential media attention. | P4: =IF(AC4>=Reference!$H$2, Reference!$G$2, IF(AC4>=Reference!$H$3, Reference!$G$3, IF(AC4>=Reference!$H$4, Reference!$G$4, IF(AC4>=Reference!$H$5, Reference!$G$5, "")))) -> Severe | Q4: =IF(F4="Physical", "Very Low", IF(F4="Local", "Low", IF(F4="Adjacent", "Medium", IF(F4="Network", "High", "")))) -> High | R4: =IF(AE4>=Reference!$D$2, Reference!$G$2, IF(AE4>=Reference!$D$3, Reference!$E$3, IF(AE4>=Reference!$D$4, Reference!$E$4, IF(AE4>=Reference!$D$5, Reference!$E$5, "")))) -> Severe | S4: Mitigation | T4: Implement stringent cryptographic verification of messages, particularly for special StationTypes (e.g., emergency vehicles).Enhanced access control and authentication measures for systems permitted to broadcast high-priority messages.Behavioral analytics to detect unexpected use of emergency-related StationTypes. | U4: Authentication and validation modules on OBUs and RSUs.Backend traffic management and monitoring systems.Emergency vehicle priority management systems. | V4: Ensuring authenticity of emergency vehicle messages is essential to maintaining public safety, operational traffic management, and preventing malicious exploitation of high-priority status. | W4: Integrity, Authenticity, Non-repudiation, Availability. | Y4: =IF(H4=Reference!$A$12, Reference!$C$12, IF(H4=Reference!$A$11, Reference!$C$11, IF(H4=Reference!$A$10, Reference!$C$10, IF(H4=Reference!$A$9, Reference!$C$9, 0)))) -> 7 | Z4: =IF(J4=Reference!$A$20, Reference!$C$20, IF(J4=Reference!$A$19, Reference!$C$19, IF(J4=Reference!$A$18, Reference!$C$18, IF(J4=Reference!$A$17, Reference!$C$17, 0)))) -> 7 | AA4: =IF(L4=Reference!$A$28, Reference!$C$28, IF(L4=Reference!$A$27, Reference!$C$27, IF(L4=Reference!$A$26, Reference!$C$26, IF(L4=Reference!$A$25, Reference!$C$25, 0)))) -> 7 | AB4: =IF(N4=Reference!$A$36, Reference!$C$36, IF(N4=Reference!$A$35, Reference!$C$35, IF(N4=Reference!$A$34, Reference!$C$34, IF(N4=Reference!$A$33, Reference!$C$33, 0)))) -> 7 | AC4: =(Reference!$B$2*Y4 + Reference!$B$3*AA4 + Reference!$B$4*Z4 + Reference!$B$5 * AB4)/4 -> 11.8125 | AD4: =IF(Q4=Reference!$C$41, Reference!$D$41, IF(Q4=Reference!$C$42, Reference!$D$42, IF(Q4=Reference!$C$43, Reference!$D$43, IF(Q4=Reference!$C$44, Reference!$D$44, 0)))) -> 10 | AE4: =1 + (AC4 * AD4) -> 119.125
A5: DENM Message Container | B5: Denial of service | C5: Availability | D5: Set a very small TxInterval | E5: The attacker gains access to the OBU software or message generation system. | F5: Network | G5: This attack modifies the transmission interval of DENMs, which occurs within the network layer responsible for message dissemination. | H5: Moderate | I5: Network congestion may delay safety-critical messages, affecting V2X efficiency and reaction times. | J5: Moderate | K5: The organization might incur minor additional costs related to bandwidth and network management | L5: Moderate | M5: while V2X network congestion can occur, vehicle operations remain unaffected. | N5: Negligible | O5: The attack does not involve personal data or compromise legal compliance. | P5: =IF(AC5>=Reference!$H$2, Reference!$G$2, IF(AC5>=Reference!$H$3, Reference!$G$3, IF(AC5>=Reference!$H$4, Reference!$G$4, IF(AC5>=Reference!$H$5, Reference!$G$5, "")))) -> Major | Q5: =IF(F5="Physical", "Very Low", IF(F5="Local", "Low", IF(F5="Adjacent", "Medium", IF(F5="Network", "High", "")))) -> High | R5: =IF(AE5>=Reference!$D$2, Reference!$G$2, IF(AE5>=Reference!$D$3, Reference!$E$3, IF(AE5>=Reference!$D$4, Reference!$E$4, IF(AE5>=Reference!$D$5, Reference!$E$5, "")))) -> High | S5: Mitigation | T5: Min TxInterval threshold, Rate Limiting, Congestion Control, IDS for flooding detection, RSU-Based Monitoring | U5: Network Congestion Control, Rate-Limiting, Priority-Based Handling, IDS & Anomaly Detection, OBU/RSU Processing, GeoNetworking | V5: Preventable by applying rate limits, congestion control, and anomaly detection. | Y5: =IF(H5=Reference!$A$12, Reference!$C$12, IF(H5=Reference!$A$11, Reference!$C$11, IF(H5=Reference!$A$10, Reference!$C$10, IF(H5=Reference!$A$9, Reference!$C$9, 0)))) -> 4 | Z5: =IF(J5=Reference!$A$20, Reference!$C$20, IF(J5=Reference!$A$19, Reference!$C$19, IF(J5=Reference!$A$18, Reference!$C$18, IF(J5=Reference!$A$17, Reference!$C$17, 0)))) -> 4 | AA5: =IF(L5=Reference!$A$28, Reference!$C$28, IF(L5=Reference!$A$27, Reference!$C$27, IF(L5=Reference!$A$26, Reference!$C$26, IF(L5=Reference!$A$25, Reference!$C$25, 0)))) -> 4 | AB5: =IF(N5=Reference!$A$36, Reference!$C$36, IF(N5=Reference!$A$35, Reference!$C$35, IF(N5=Reference!$A$34, Reference!$C$34, IF(N5=Reference!$A$33, Reference!$C$33, 0)))) -> 1 | AC5: =(Reference!$B$2*Y5 + Reference!$B$3*AA5 + Reference!$B$4*Z5 + Reference!$B$5 * AB5)/4 -> 6.5625 | AD5: =IF(Q5=Reference!$C$41, Reference!$D$41, IF(Q5=Reference!$C$42, Reference!$D$42, IF(Q5=Reference!$C$43, Reference!$D$43, IF(Q5=Reference!$C$44, Reference!$D$44, 0)))) -> 10 | AE5: =1 + (AC5 * AD5) -> 66.625
A6: DENM Message Container | B6: Tampering | C6: Integrity | D6: Set an inconsistent value of Sub-CauseCode with the context (e.g., requesting winter service during summer) | E6: the attacker modifies the Sub-CauseCode through OBU before broadcasting the manipulated DENM message. | F6: Network | G6: The attack is executed by modifying DENM messages within the OBU before they are broadcast over V2X communication channels (DSRC or C-V2X). | H6: Moderate | I6: The attack does not directly threaten vehicle safety, it can cause disruptions in automated decision-making, traffic inefficiencies, and misallocation of emergency resources. | J6: Moderate | K6: It can lead to waste of operational resources, traffic inefficiencies, and loss of trust in V2X technology, which can impact OEMs, fleet operators, and road authorities financially. | L6: Moderate | M6: It reduces the reliability of traffic event notifications, leading to inefficiencies in resource allocation and vehicle decision-making. | N6: Negligible | O6: No direct privacy violations occur, as the attack does not involve personal data or unauthorized access. | P6: =IF(AC6>=Reference!$H$2, Reference!$G$2, IF(AC6>=Reference!$H$3, Reference!$G$3, IF(AC6>=Reference!$H$4, Reference!$G$4, IF(AC6>=Reference!$H$5, Reference!$G$5, "")))) -> Major | Q6: =IF(F6="Physical", "Very Low", IF(F6="Local", "Low", IF(F6="Adjacent", "Medium", IF(F6="Network", "High", "")))) -> High | R6: =IF(AE6>=Reference!$D$2, Reference!$E$2, IF(AE6>=Reference!$D$3, Reference!$E$3, IF(AE6>=Reference!$D$4, Reference!$E$4, IF(AE6>=Reference!$D$5, Reference!$E$5, "")))) -> High | S6: Mitigation | T6: Cross-validation with sensors, digital signatures, anomaly detection, trust scoring | U6: V2X Message Authentication & Integrity (PKI, Certificates),Event Processing in Vehicles & RSUs | V6: Avoidance is not feasible, as DENMs are a fundamental part of V2X communication and cannot be eliminated. | Y6: =IF(H6=Reference!$A$12, Reference!$C$12, IF(H6=Reference!$A$11, Reference!$C$11, IF(H6=Reference!$A$10, Reference!$C$10, IF(H6=Reference!$A$9, Reference!$C$9, 0)))) -> 4 | Z6: =IF(J6=Reference!$A$20, Reference!$C$20, IF(J6=Reference!$A$19, Reference!$C$19, IF(J6=Reference!$A$18, Reference!$C$18, IF(J6=Reference!$A$17, Reference!$C$17, 0)))) -> 4 | AA6: =IF(L6=Reference!$A$28, Reference!$C$28, IF(L6=Reference!$A$27, Reference!$C$27, IF(L6=Reference!$A$26, Reference!$C$26, IF(L6=Reference!$A$25, Reference!$C$25, 0)))) -> 4 | AB6: =IF(N6=Reference!$A$36, Reference!$C$36, IF(N6=Reference!$A$35, Reference!$C$35, IF(N6=Reference!$A$34, Reference!$C$34, IF(N6=Reference!$A$33, Reference!$C$33, 0)))) -> 1 | AC6: =(Reference!$B$2*Y6 + Reference!$B$3*AA6 + Reference!$B$4*Z6 + Reference!$B$5 * AB6)/4 -> 6.5625 | AD6: =IF(Q6=Reference!$C$41, Reference!$D$41, IF(Q6=Reference!$C$42, Reference!$D$42, IF(Q6=Reference!$C$43, Reference!$D$43, IF(Q6=Reference!$C$44, Reference!$D$44, 0)))) -> 10 | AE6: =1 + (AC6 * AD6) -> 66.625
A7: DENM Message Container | B7: Tampering | C7: Integrity | D7: The attacker modifies the CauseCode field in the Situation Container of a DENM to provide false or misleading information.(e.g "Accident" is assigned to a simple roadwork event, possibly triggering unnecessary emergency responses.) | E7: Gain Access to the OBU’s V2X Communication Stack to Exploit firmware vulnerabilities, misconfigured permissions, or debugging interfaces. | F7: Network | G7: The attack is executed by modifying DENM messages within the OBU before they are broadcast over V2X communication channels. | H7: Major | I7: False reports can directly impact traffic safety, particularly for automated driving systems that rely on V2X data. | J7: Moderate | K7: While not catastrophic, misallocated resources, traffic congestion, and reputation damage can lead to financial losses. | L7: Major | M7: The attack does not fully disable V2X, but it can cause significant traffic disruptions, emergency misallocations, and trust degradation. | N7: Negligible | O7: No direct privacy violation, but false emergency responses could create legal issues over time. | P7: =IF(AC7>=Reference!$H$2, Reference!$G$2, IF(AC7>=Reference!$H$3, Reference!$G$3, IF(AC7>=Reference!$H$4, Reference!$G$4, IF(AC7>=Reference!$H$5, Reference!$G$5, "")))) -> Severe | Q7: =IF(F7="Physical", "Very Low", IF(F7="Local", "Low", IF(F7="Adjacent", "Medium", IF(F7="Network", "High", "")))) -> High | R7: =IF(AE7>=Reference!$D$2, Reference!$G$2, IF(AE7>=Reference!$D$3, Reference!$E$3, IF(AE7>=Reference!$D$4, Reference!$E$4, IF(AE7>=Reference!$D$5, Reference!$E$5, "")))) -> Severe | S7: Mitigation | T7: Cross-Validation with Sensor Data&Message Authentication & Digital Signatures | U7: V2X Message Authentication & Integrity,Event Processing in Vehicles & RSUs | Y7: =IF(H7=Reference!$A$12, Reference!$C$12, IF(H7=Reference!$A$11, Reference!$C$11, IF(H7=Reference!$A$10, Reference!$C$10, IF(H7=Reference!$A$9, Reference!$C$9, 0)))) -> 7 | Z7: =IF(J7=Reference!$A$20, Reference!$C$20, IF(J7=Reference!$A$19, Reference!$C$19, IF(J7=Reference!$A$18, Reference!$C$18, IF(J7=Reference!$A$17, Reference!$C$17, 0)))) -> 4 | AA7: =IF(L7=Reference!$A$28, Reference!$C$28, IF(L7=Reference!$A$27, Reference!$C$27, IF(L7=Reference!$A$26, Reference!$C$26, IF(L7=Reference!$A$25, Reference!$C$25, 0)))) -> 7 | AB7: =IF(N7=Reference!$A$36, Reference!$C$36, IF(N7=Reference!$A$35, Reference!$C$35, IF(N7=Reference!$A$34, Reference!$C$34, IF(N7=Reference!$A$33, Reference!$C$33, 0)))) -> 1 | AC7: =(Reference!$B$2*Y7 + Reference!$B$3*AA7 + Reference!$B$4*Z7 + Reference!$B$5 * AB7)/4 -> 11.0625 | AD7: =IF(Q7=Reference!$C$41, Reference!$D$41, IF(Q7=Reference!$C$42, Reference!$D$42, IF(Q7=Reference!$C$43, Reference!$D$43, IF(Q7=Reference!$C$44, Reference!$D$44, 0)))) -> 10 | AE7: =1 + (AC7 * AD7) -> 111.625
A8: DENM Message Container | B8: Tampering | C8: Integrity | D8: The attacker modifies or inserts new path points in the Traces field within the Location Container, creating an incorrect path history of a road event. | E8: Attacker gains access to the OBU’s V2X Communication Stack to exploit firmware vulnerabilities, misconfigured permissions, or debugging interfaces. | F8: Network | G8: The attack is executed by modifying DENM messages within the OBU before they are broadcast over V2X communication channels. | H8: Moderate | I8: False path data can disrupt navigation and vehicle decision-making, but does not directly compromise vehicle control. | J8: Moderate | K8: While not catastrophic, misallocated resources, traffic congestion, and reputation damage can lead to financial losses. | L8: Major | M8: The attack does not fully disable V2X, but it can cause significant traffic disruptions, emergency misallocations, and trust degradation. | N8: Negligible | O8: No direct privacy violation, but false emergency responses could create legal issues over time. | P8: =IF(AC8>=Reference!$H$2, Reference!$G$2, IF(AC8>=Reference!$H$3, Reference!$G$3, IF(AC8>=Reference!$H$4, Reference!$G$4, IF(AC8>=Reference!$H$5, Reference!$G$5, "")))) -> Major | Q8: =IF(F8="Physical", "Very Low", IF(F8="Local", "Low", IF(F8="Adjacent", "Medium", IF(F8="Network", "High", "")))) -> High | R8: =IF(AE8>=Reference!$D$2, Reference!$G$2, IF(AE8>=Reference!$D$3, Reference!$E$3, IF(AE8>=Reference!$D$4, Reference!$E$4, IF(AE8>=Reference!$D$5, Reference!$E$5, "")))) -> High | S8: Mitigation | T8: Cross-Validation with Sensor Data,Historical Consistency Checks | U8: V2X Message Authentication & Integrity, Event Processing in Vehicles & RSUs | Y8: =IF(H8=Reference!$A$12, Reference!$C$12, IF(H8=Reference!$A$11, Reference!$C$11, IF(H8=Reference!$A$10, Reference!$C$10, IF(H8=Reference!$A$9, Reference!$C$9, 0)))) -> 4 | Z8: =IF(J8=Reference!$A$20, Reference!$C$20, IF(J8=Reference!$A$19, Reference!$C$19, IF(J8=Reference!$A$18, Reference!$C$18, IF(J8=Reference!$A$17, Reference!$C$17, 0)))) -> 4 | AA8: =IF(L8=Reference!$A$28, Reference!$C$28, IF(L8=Reference!$A$27, Reference!$C$27, IF(L8=Reference!$A$26, Reference!$C$26, IF(L8=Reference!$A$25, Reference!$C$25, 0)))) -> 7 | AB8: =IF(N8=Reference!$A$36, Reference!$C$36, IF(N8=Reference!$A$35, Reference!$C$35, IF(N8=Reference!$A$34, Reference!$C$34, IF(N8=Reference!$A$33, Reference!$C$33, 0)))) -> 1 | AC8: =(Reference!$B$2*Y8 + Reference!$B$3*AA8 + Reference!$B$4*Z8 + Reference!$B$5 * AB8)/4 -> 7.3125 | AD8: =IF(Q8=Reference!$C$41, Reference!$D$41, IF(Q8=Reference!$C$42, Reference!$D$42, IF(Q8=Reference!$C$43, Reference!$D$43, IF(Q8=Reference!$C$44, Reference!$D$44, 0)))) -> 10 | AE8: =1 + (AC8 * AD8) -> 74.125
A9: DENM Message Container | B9: Spoofing | C9: Integrity | D9: The attacker modifies the VehicleIdentification field in the A La Carte Container, making it appear as if the DENM was sent from another legitimate vehicle. | E9: Attacker gains access to the OBU’s V2X Communication Stack to exploit firmware vulnerabilities, misconfigured permissions, or debugging interfaces. | F9: Network | G9: The attack is executed by modifying DENM messages within the OBU before they are broadcast over V2X communication channels. | H9: Negligible | I9: This attack does not pose a direct safety risk, but can degrade the trust and efficiency of V2X communications. | J9: Moderate | K9: The financial impact is minimal, as the attack does not cause direct economic losses but may require mitigation costs for improved authentication mechanisms. | L9: Negligible | M9: The attack does not fully disrupt V2X, but it can cause trust degradation and minor disruptions in vehicle identification systems. | N9: Major | O9: Spoofing vehicle identification in V2X communications can lead to privacy violations affecting vehicle owners and operators. Impersonation of a legitimate vehicle could result in legal issues, misuse of stolen identities for unauthorized actions, and potential financial penalties for affected stakeholders. | P9: =IF(AC9>=Reference!$H$2, Reference!$G$2, IF(AC9>=Reference!$H$3, Reference!$G$3, IF(AC9>=Reference!$H$4, Reference!$G$4, IF(AC9>=Reference!$H$5, Reference!$G$5, "")))) -> Negligible | Q9: =IF(F9="Physical", "Very Low", IF(F9="Local", "Low", IF(F9="Adjacent", "Medium", IF(F9="Network", "High", "")))) -> High | R9: =IF(AE9>=Reference!$D$2, Reference!$G$2, IF(AE9>=Reference!$D$3, Reference!$E$3, IF(AE9>=Reference!$D$4, Reference!$E$4, IF(AE9>=Reference!$D$5, Reference!$E$5, "")))) -> Medium | S9: Mitigation | T9: Public Key Infrastructure (PKI) for Vehicle Authentication | U9: V2X Message Authentication & Integrity | V9: Best approach, as authentication mechanisms can detect and prevent identity spoofing. | Y9: =IF(H9=Reference!$A$12, Reference!$C$12, IF(H9=Reference!$A$11, Reference!$C$11, IF(H9=Reference!$A$10, Reference!$C$10, IF(H9=Reference!$A$9, Reference!$C$9, 0)))) -> 1 | Z9: =IF(J9=Reference!$A$20, Reference!$C$20, IF(J9=Reference!$A$19, Reference!$C$19, IF(J9=Reference!$A$18, Reference!$C$18, IF(J9=Reference!$A$17, Reference!$C$17, 0)))) -> 4 | AA9: =IF(L9=Reference!$A$28, Reference!$C$28, IF(L9=Reference!$A$27, Reference!$C$27, IF(L9=Reference!$A$26, Reference!$C$26, IF(L9=Reference!$A$25, Reference!$C$25, 0)))) -> 1 | AB9: =IF(N9=Reference!$A$36, Reference!$C$36, IF(N9=Reference!$A$35, Reference!$C$35, IF(N9=Reference!$A$34, Reference!$C$34, IF(N9=Reference!$A$33, Reference!$C$33, 0)))) -> 7 | AC9: =(Reference!$B$2*Y9 + Reference!$B$3*AA9 + Reference!$B$4*Z9 + Reference!$B$5 * AB9)/4 -> 2.4375 | AD9: =IF(Q9=Reference!$C$41, Reference!$D$41, IF(Q9=Reference!$C$42, Reference!$D$42, IF(Q9=Reference!$C$43, Reference!$D$43, IF(Q9=Reference!$C$44, Reference!$D$44, 0)))) -> 10 | AE9: =1 + (AC9 * AD9) -> 25.375
B10: Information disclosure | C10: Confidentiality | D10: The attacker modifies the VehicleIdentification field in the A La Carte Container, making it appear as if the DENM was sent from another legitimate vehicle. | E10: Attacker gains access to the OBU’s V2X Communication Stack to exploit firmware vulnerabilities, misconfigured permissions, or debugging interfaces. | F10: Network | G10: The attack is executed by modifying DENM messages within the OBU before they are broadcast over V2X communication channels. | H10: Negligible | I10: This attack does not pose a direct safety risk, but can degrade the trust and efficiency of V2X communications. | J10: Moderate | K10: The financial impact is minimal, as the attack does not cause direct economic losses but may require mitigation costs for improved authentication mechanisms. | L10: Negligible | M10: The attack does not fully disrupt V2X, but it can cause trust degradation and minor disruptions in vehicle identification systems. | N10: Major | O10: Spoofing vehicle identification in V2X communications can lead to privacy violations affecting vehicle owners and operators. Impersonation of a legitimate vehicle could result in legal issues, misuse of stolen identities for unauthorized actions, and potential financial penalties for affected stakeholders. | P10: =IF(AC10>=Reference!$H$2, Reference!$G$2, IF(AC10>=Reference!$H$3, Reference!$G$3, IF(AC10>=Reference!$H$4, Reference!$G$4, IF(AC10>=Reference!$H$5, Reference!$G$5, "")))) -> Negligible | Q10: =IF(F10="Physical", "Very Low", IF(F10="Local", "Low", IF(F10="Adjacent", "Medium", IF(F10="Network", "High", "")))) -> High | R10: =IF(AE10>=Reference!$D$2, Reference!$G$2, IF(AE10>=Reference!$D$3, Reference!$E$3, IF(AE10>=Reference!$D$4, Reference!$E$4, IF(AE10>=Reference!$D$5, Reference!$E$5, "")))) -> Medium | S10: Mitigation | T10: Public Key Infrastructure (PKI) for Vehicle Authentication | U10: V2X Message Authentication & Integrity | V10: Best approach, as authentication mechanisms can detect and prevent identity spoofing. | Y10: =IF(H10=Reference!$A$12, Reference!$C$12, IF(H10=Reference!$A$11, Reference!$C$11, IF(H10=Reference!$A$10, Reference!$C$10, IF(H10=Reference!$A$9, Reference!$C$9, 0)))) -> 1 | Z10: =IF(J10=Reference!$A$20, Reference!$C$20, IF(J10=Reference!$A$19, Reference!$C$19, IF(J10=Reference!$A$18, Reference!$C$18, IF(J10=Reference!$A$17, Reference!$C$17, 0)))) -> 4 | AA10: =IF(L10=Reference!$A$28, Reference!$C$28, IF(L10=Reference!$A$27, Reference!$C$27, IF(L10=Reference!$A$26, Reference!$C$26, IF(L10=Reference!$A$25, Reference!$C$25, 0)))) -> 1 | AB10: =IF(N10=Reference!$A$36, Reference!$C$36, IF(N10=Reference!$A$35, Reference!$C$35, IF(N10=Reference!$A$34, Reference!$C$34, IF(N10=Reference!$A$33, Reference!$C$33, 0)))) -> 7 | AC10: =(Reference!$B$2*Y10 + Reference!$B$3*AA10 + Reference!$B$4*Z10 + Reference!$B$5 * AB10)/4 -> 2.4375 | AD10: =IF(Q10=Reference!$C$41, Reference!$D$41, IF(Q10=Reference!$C$42, Reference!$D$42, IF(Q10=Reference!$C$43, Reference!$D$43, IF(Q10=Reference!$C$44, Reference!$D$44, 0)))) -> 10 | AE10: =1 + (AC10 * AD10) -> 25.375
A11: DENM Message Container | B11: Tampering | C11: Integrity | D11: The attacker modifies the Lane Position field in the A La Carte Container, making it appear as if a road event (e.g., accident, road closure, stationary vehicle) is occurring in the wrong lane or road, causing vehicles to receive incorrect hazard locations, potentially leading to accidents. | E11: Attacker gains access to the OBU’s V2X Communication Stack to exploit firmware vulnerabilities, misconfigured permissions, or debugging interfaces. | F11: Network | G11: The attack is executed by modifying DENM messages within the OBU before they are broadcast over V2X communication channels. | H11: Severe | I11: False lane reports can directly impact traffic safety, particularly for automated driving systems that rely on V2X data. | J11: Severe | K11: Severe accidents due to incorrect lane positioning could lead to fatalities, lawsuits, regulatory fines, and reputational damage, posing an existential financial risk for OEMs and infrastructure operators. | L11: Severe | M11: Incorrect lane positioning can mislead vehicle control systems, potentially leading to incorrect lane changes or unsafe driving behavior, severely affecting vehicle operation and regulatory compliance. | N11: Negligible | O11: No direct privacy violation, but false lane reports could create legal concerns regarding accident liability. | P11: =IF(AC11>=Reference!$H$2, Reference!$G$2, IF(AC11>=Reference!$H$3, Reference!$G$3, IF(AC11>=Reference!$H$4, Reference!$G$4, IF(AC11>=Reference!$H$5, Reference!$G$5, "")))) -> Severe | Q11: =IF(F11="Physical", "Very Low", IF(F11="Local", "Low", IF(F11="Adjacent", "Medium", IF(F11="Network", "High", "")))) -> High | R11: =IF(AE11>=Reference!$D$2, Reference!$G$2, IF(AE11>=Reference!$D$3, Reference!$E$3, IF(AE11>=Reference!$D$4, Reference!$E$4, IF(AE11>=Reference!$D$5, Reference!$E$5, "")))) -> Severe | S11: Mitigation | T11: Cross-Validation with Sensor Data,Historical Consistency Checks,Message Authentication & Digital Signatures | U11: V2X Message Authentication & Integrity | V11: Authentication mechanisms can detect and prevent lane tampering. | Y11: =IF(H11=Reference!$A$12, Reference!$C$12, IF(H11=Reference!$A$11, Reference!$C$11, IF(H11=Reference!$A$10, Reference!$C$10, IF(H11=Reference!$A$9, Reference!$C$9, 0)))) -> 10 | Z11: =IF(J11=Reference!$A$20, Reference!$C$20, IF(J11=Reference!$A$19, Reference!$C$19, IF(J11=Reference!$A$18, Reference!$C$18, IF(J11=Reference!$A$17, Reference!$C$17, 0)))) -> 10 | AA11: =IF(L11=Reference!$A$28, Reference!$C$28, IF(L11=Reference!$A$27, Reference!$C$27, IF(L11=Reference!$A$26, Reference!$C$26, IF(L11=Reference!$A$25, Reference!$C$25, 0)))) -> 10 | AB11: =IF(N11=Reference!$A$36, Reference!$C$36, IF(N11=Reference!$A$35, Reference!$C$35, IF(N11=Reference!$A$34, Reference!$C$34, IF(N11=Reference!$A$33, Reference!$C$33, 0)))) -> 1 | AC11: =(Reference!$B$2*Y11 + Reference!$B$3*AA11 + Reference!$B$4*Z11 + Reference!$B$5 * AB11)/4 -> 16.3125 | AD11: =IF(Q11=Reference!$C$41, Reference!$D$41, IF(Q11=Reference!$C$42, Reference!$D$42, IF(Q11=Reference!$C$43, Reference!$D$43, IF(Q11=Reference!$C$44, Reference!$D$44, 0)))) -> 10 | AE11: =1 + (AC11 * AD11) -> 164.125
A12: DENM Message Container | B12: Elevation of privilege | C12: Integrity | D12: The attacker modifies the VehicleIdentification field to impersonate or access resources specific to high-value or critical vehicles (e.g., emergency vehicles, luxury cars). | E12: Attacker gains access to the OBU’s V2X Communication Stack to exploit firmware vulnerabilities or debugging interfaces and inject malicious software via physical access or over-the-air updates. | F12: Network | G12: The attack is executed by modifying outgoing DENM messages through the OBU, and the malicious messages are transmitted over the network to other entities. | H12: Severe | I12: Misuse of VehicleIdentification can lead to severe accidents, life-threatening injuries, or fatalities. | J12: Severe | K12: Vehicle theft or misuse can cause significant financial damage that could threaten organizational sustainability. | L12: Severe | M12: Exploiting high-value vehicles or resource allocation mechanisms can significantly degrade system functionality. | N12: Severe | O12: Widespread misuse of VehicleIdentification can trigger legal consequences and media attention. | P12: =IF(AC12>=Reference!$H$2, Reference!$G$2, IF(AC12>=Reference!$H$3, Reference!$G$3, IF(AC12>=Reference!$H$4, Reference!$G$4, IF(AC12>=Reference!$H$5, Reference!$G$5, "")))) -> Severe | Q12: =IF(F12="Physical", "Very Low", IF(F12="Local", "Low", IF(F12="Adjacent", "Medium", IF(F12="Network", "High", "")))) -> High | R12: =IF(AE12>=Reference!$D$2, Reference!$G$2, IF(AE12>=Reference!$D$3, Reference!$E$3, IF(AE12>=Reference!$D$4, Reference!$E$4, IF(AE12>=Reference!$D$5, Reference!$E$5, "")))) -> Severe | S12: Mitigation | T12: Public Key Infrastructure (PKI) for Vehicle Authentication ,Rate Limiting for VehicleIdentification Updates | U12: V2X Message Authentication & Integrity,Trust & Reputation Systems,Event Processing in Vehicles & RSUs | V12: Best approach, involving detection, authentication, and anomaly detection | Y12: =IF(H12=Reference!$A$12, Reference!$C$12, IF(H12=Reference!$A$11, Reference!$C$11, IF(H12=Reference!$A$10, Reference!$C$10, IF(H12=Reference!$A$9, Reference!$C$9, 0)))) -> 10 | Z12: =IF(J12=Reference!$A$20, Reference!$C$20, IF(J12=Reference!$A$19, Reference!$C$19, IF(J12=Reference!$A$18, Reference!$C$18, IF(J12=Reference!$A$17, Reference!$C$17, 0)))) -> 10 | AA12: =IF(L12=Reference!$A$28, Reference!$C$28, IF(L12=Reference!$A$27, Reference!$C$27, IF(L12=Reference!$A$26, Reference!$C$26, IF(L12=Reference!$A$25, Reference!$C$25, 0)))) -> 10 | AB12: =IF(N12=Reference!$A$36, Reference!$C$36, IF(N12=Reference!$A$35, Reference!$C$35, IF(N12=Reference!$A$34, Reference!$C$34, IF(N12=Reference!$A$33, Reference!$C$33, 0)))) -> 10 | AC12: =(Reference!$B$2*Y12 + Reference!$B$3*AA12 + Reference!$B$4*Z12 + Reference!$B$5 * AB12)/4 -> 16.875 | AD12: =IF(Q12=Reference!$C$41, Reference!$D$41, IF(Q12=Reference!$C$42, Reference!$D$42, IF(Q12=Reference!$C$43, Reference!$D$43, IF(Q12=Reference!$C$44, Reference!$D$44, 0)))) -> 10 | AE12: =1 + (AC12 * AD12) -> 169.75
A13: High Frequency (HF) Container in CAM Messages | B13: Tampering | C13: Integrity | D13: An attacker modifies the speed value within the HF container of outgoing CAM messages to falsely indicate that the vehicle ahead is moving slower or is stationary. | E13: Attacker gains access to the OBU’s V2X Communication System to exploit vulnerabilities in the vehicle’s firmware or OBU and inject malicious software or commands through physical or wireless access. | F13: Network | G13: The tampered speed value is broadcast via compromised CAM messages over the V2X network, impacting other vehicles. | H13: Severe | I13: The HF container includes vehicle speed, critical for detecting collisions. Tampering with this can cause hard braking, evasive maneuvers, or incorrect responses, leading to life-threatening situations and potential fatalities. This risk is especially high for autonomous vehicles. | J13: Severe | K13: Severe collisions could result in vehicle damage, emergency response costs, legal penalties, and loss of trust in V2X technology, affecting OEMs financially. | L13: Severe | M13: Severe collisions could result in vehicle damage, emergency response costs, legal penalties, and loss of trust in V2X technology, affecting OEMs financially. | N13: Moderate | O13: Since the HF container doesn’t contain personal identifiers, the privacy impact is low, but legal liability may arise from collisions caused by tampered data. | P13: =IF(AC13>=Reference!$H$2, Reference!$G$2, IF(AC13>=Reference!$H$3, Reference!$G$3, IF(AC13>=Reference!$H$4, Reference!$G$4, IF(AC13>=Reference!$H$5, Reference!$G$5, "")))) -> Severe | Q13: =IF(F13="Physical", "Very Low", IF(F13="Local", "Low", IF(F13="Adjacent", "Medium", IF(F13="Network", "High", "")))) -> High | R13: =IF(AE13>=Reference!$D$2, Reference!$G$2, IF(AE13>=Reference!$D$3, Reference!$E$3, IF(AE13>=Reference!$D$4, Reference!$E$4, IF(AE13>=Reference!$D$5, Reference!$E$5, "")))) -> Severe | S13: Mitigation | T13: Message Authentication & Digital Signatures,Anomaly Detection Systems,Cross-Validation with Onboard Sensors | V13: Best approach, involving message authentication, cross-verification, and anomaly detection. | Y13: =IF(H13=Reference!$A$12, Reference!$C$12, IF(H13=Reference!$A$11, Reference!$C$11, IF(H13=Reference!$A$10, Reference!$C$10, IF(H13=Reference!$A$9, Reference!$C$9, 0)))) -> 10 | Z13: =IF(J13=Reference!$A$20, Reference!$C$20, IF(J13=Reference!$A$19, Reference!$C$19, IF(J13=Reference!$A$18, Reference!$C$18, IF(J13=Reference!$A$17, Reference!$C$17, 0)))) -> 10 | AA13: =IF(L13=Reference!$A$28, Reference!$C$28, IF(L13=Reference!$A$27, Reference!$C$27, IF(L13=Reference!$A$26, Reference!$C$26, IF(L13=Reference!$A$25, Reference!$C$25, 0)))) -> 10 | AB13: =IF(N13=Reference!$A$36, Reference!$C$36, IF(N13=Reference!$A$35, Reference!$C$35, IF(N13=Reference!$A$34, Reference!$C$34, IF(N13=Reference!$A$33, Reference!$C$33, 0)))) -> 4 | AC13: =(Reference!$B$2*Y13 + Reference!$B$3*AA13 + Reference!$B$4*Z13 + Reference!$B$5 * AB13)/4 -> 16.5 | AD13: =IF(Q13=Reference!$C$41, Reference!$D$41, IF(Q13=Reference!$C$42, Reference!$D$42, IF(Q13=Reference!$C$43, Reference!$D$43, IF(Q13=Reference!$C$44, Reference!$D$44, 0)))) -> 10 | AE13: =1 + (AC13 * AD13) -> 166
A14: High Frequency (HF) Container in CAM Messages | B14: Spoofing | C14: Integrity | D14: An attacker injects false CAM messages with incorrect position data, causing the receiving vehicle to believe that an adjacent lane is occupied when it’s actually clear or vice versa. | E14: Through Externally Injected or Compromised OBU CAM Messages | F14: Network | G14: The spoofed vehicle position is transmitted via compromised CAM messages over the V2X network, impacting the lane change logic of other vehicles. | H14: Major | I14: Spoofed vehicle positions can cause side collisions during lane changes, especially at high speeds or in heavy traffic. The threat is particularly critical for autonomous and semi-autonomous vehicles relying on CAMs for situational awareness. | J14: Major | K14: Damage to vehicles due to side collisions could lead to repair costs, insurance claims, and legal liabilities for the OEM or vehicle owners. | L14: Major | M14: Incorrect lane change warnings could cause delays or temporary traffic disruptions, but these would be localized unless multiple vehicles are affected simultaneously. | N14: Major | O14: Limited privacy concerns, but if collisions occur, regulatory investigations or legal action may arise due to improper handling of spoofed messages. | P14: =IF(AC14>=Reference!$H$2, Reference!$G$2, IF(AC14>=Reference!$H$3, Reference!$G$3, IF(AC14>=Reference!$H$4, Reference!$G$4, IF(AC14>=Reference!$H$5, Reference!$G$5, "")))) -> Severe | Q14: =IF(F14="Physical", "Very Low", IF(F14="Local", "Low", IF(F14="Adjacent", "Medium", IF(F14="Network", "High", "")))) -> High | R14: =IF(AE14>=Reference!$D$2, Reference!$G$2, IF(AE14>=Reference!$D$3, Reference!$E$3, IF(AE14>=Reference!$D$4, Reference!$E$4, IF(AE14>=Reference!$D$5, Reference!$E$5, "")))) -> Severe | S14: Mitigation | T14: Message Authentication & Digital Signatures,Cross-Validation with Onboard Sensors,Anomaly Detection Systems | U14: High Frequency (HF) Container,Position Verification Mechanisms,Lane Change Assistance Systems,Traffic Coordination Systems | V14: Best approach, involving message authentication, cross-validation, and anomaly detection. | Y14: =IF(H14=Reference!$A$12, Reference!$C$12, IF(H14=Reference!$A$11, Reference!$C$11, IF(H14=Reference!$A$10, Reference!$C$10, IF(H14=Reference!$A$9, Reference!$C$9, 0)))) -> 7 | Z14: =IF(J14=Reference!$A$20, Reference!$C$20, IF(J14=Reference!$A$19, Reference!$C$19, IF(J14=Reference!$A$18, Reference!$C$18, IF(J14=Reference!$A$17, Reference!$C$17, 0)))) -> 7 | AA14: =IF(L14=Reference!$A$28, Reference!$C$28, IF(L14=Reference!$A$27, Reference!$C$27, IF(L14=Reference!$A$26, Reference!$C$26, IF(L14=Reference!$A$25, Reference!$C$25, 0)))) -> 7 | AB14: =IF(N14=Reference!$A$36, Reference!$C$36, IF(N14=Reference!$A$35, Reference!$C$35, IF(N14=Reference!$A$34, Reference!$C$34, IF(N14=Reference!$A$33, Reference!$C$33, 0)))) -> 7 | AC14: =(Reference!$B$2*Y14 + Reference!$B$3*AA14 + Reference!$B$4*Z14 + Reference!$B$5 * AB14)/4 -> 11.8125 | AD14: =IF(Q14=Reference!$C$41, Reference!$D$41, IF(Q14=Reference!$C$42, Reference!$D$42, IF(Q14=Reference!$C$43, Reference!$D$43, IF(Q14=Reference!$C$44, Reference!$D$44, 0)))) -> 10 | AE14: =1 + (AC14 * AD14) -> 119.125
A15: Basic Container in CAM Messages | B15: Spoofing | C15: Integrity | D15: The attacker broadcasts CAM messages indicating that their vehicle is an emergency vehicle using a spoofed Vehicle Role or Vehicle Identification in the Basic Container. | E15: Through Compromised OBU or Externally Spoofed CAMs | F15: Network | G15: The spoofed emergency vehicle CAMs are transmitted over the V2X network, impacting multiple vehicles and traffic systems. | H15: Major | I15: Delays in yielding to actual emergency vehicles can result in life-threatening injuries if medical or police assistance is delayed. False yielding could also cause accidents if vehicles react incorrectly. | J15: Major | K15: False yielding could cause damage to vehicles, delays in goods transportation, and legal liabilities for OEMs and traffic system operators. | L15: Severe | M15: Emergency response delays and misuse of traffic resources could cause widespread traffic disruptions. | N15: Severe | O15: High legislative impact due to potential regulatory violations involving misuse of emergency vehicle privileges. Repeated incidents could result in legal action against system operators or OEMs | P15: =IF(AC15>=Reference!$H$2, Reference!$G$2, IF(AC15>=Reference!$H$3, Reference!$G$3, IF(AC15>=Reference!$H$4, Reference!$G$4, IF(AC15>=Reference!$H$5, Reference!$G$5, "")))) -> Severe | Q15: =IF(F15="Physical", "Very Low", IF(F15="Local", "Low", IF(F15="Adjacent", "Medium", IF(F15="Network", "High", "")))) -> High | R15: =IF(AE15>=Reference!$D$2, Reference!$G$2, IF(AE15>=Reference!$D$3, Reference!$E$3, IF(AE15>=Reference!$D$4, Reference!$E$4, IF(AE15>=Reference!$D$5, Reference!$E$5, "")))) -> Severe | S15: Mitigation | T15: Certificate-Based Authentication,Cross-Validation with Other Sensors or Traffic Cameras,SSP Permissions Enforcement | U15: Basic Container (Vehicle Role/Identification),V2X Message Verification & Trust Mechanisms,Traffic Light Control Systems | V15: Best option, involving message authentication, cross-validation, and privilege-based access. | Y15: =IF(H15=Reference!$A$12, Reference!$C$12, IF(H15=Reference!$A$11, Reference!$C$11, IF(H15=Reference!$A$10, Reference!$C$10, IF(H15=Reference!$A$9, Reference!$C$9, 0)))) -> 7 | Z15: =IF(J15=Reference!$A$20, Reference!$C$20, IF(J15=Reference!$A$19, Reference!$C$19, IF(J15=Reference!$A$18, Reference!$C$18, IF(J15=Reference!$A$17, Reference!$C$17, 0)))) -> 7 | AA15: =IF(L15=Reference!$A$28, Reference!$C$28, IF(L15=Reference!$A$27, Reference!$C$27, IF(L15=Reference!$A$26, Reference!$C$26, IF(L15=Reference!$A$25, Reference!$C$25, 0)))) -> 10 | AB15: =IF(N15=Reference!$A$36, Reference!$C$36, IF(N15=Reference!$A$35, Reference!$C$35, IF(N15=Reference!$A$34, Reference!$C$34, IF(N15=Reference!$A$33, Reference!$C$33, 0)))) -> 10 | AC15: =(Reference!$B$2*Y15 + Reference!$B$3*AA15 + Reference!$B$4*Z15 + Reference!$B$5 * AB15)/4 -> 12.75 | AD15: =IF(Q15=Reference!$C$41, Reference!$D$41, IF(Q15=Reference!$C$42, Reference!$D$42, IF(Q15=Reference!$C$43, Reference!$D$43, IF(Q15=Reference!$C$44, Reference!$D$44, 0)))) -> 10 | AE15: =1 + (AC15 * AD15) -> 128.5
B16: Tampering | C16: Integrity | D16: The attacker intentionally alters the Station Type field within the Basic Container of the CAM message, switching it between valid types (e.g., from personal vehicle to public transport or infrastructure unit). This manipulation can be used to bypass access controls, filtering, or prioritization mechanisms in receiving ITS-S nodes or RSUs, allowing malicious data to be accepted or propagated. | E16: The attacker, having access to the ITS-S stack (via software exploit or unauthorized configuration), modifies the Station Type field during CAM composition. CAMs are then periodically sent via standard CA service routines, but now with misleading identity type, triggering wrong trust assumptions. | F16: Local | G16: The attacker has internal access to the originating ITS-S software (e.g., compromised onboard unit). | H16: Moderate | I16: A spoofed station type could cause traffic to respond inappropriately (e.g., yielding to a fake emergency vehicle or treating a malicious node as an RSU), potentially causing unsafe behavior. | J16: Moderate | K16: Minimal direct financial damage unless used as part of broader attack (e.g., toll evasion or infrastructure abuse). | L16: Major | M16: Disrupts traffic flow logic, network prioritization, and service-specific policies (e.g., rerouting, prioritization). | N16: Moderate | O16: Misuse of station identity can breach regulatory compliance (e.g., impersonating emergency vehicles) and may expose legal liability to OEMs or operators. | P16: =IF(AC16>=Reference!$H$2, Reference!$G$2, IF(AC16>=Reference!$H$3, Reference!$G$3, IF(AC16>=Reference!$H$4, Reference!$G$4, IF(AC16>=Reference!$H$5, Reference!$G$5, "")))) -> Major | Q16: =IF(F16="Physical", "Very Low", IF(F16="Local", "Low", IF(F16="Adjacent", "Medium", IF(F16="Network", "High", "")))) -> Low | R16: =IF(AE16>=Reference!$D$2, Reference!$G$2, IF(AE16>=Reference!$D$3, Reference!$E$3, IF(AE16>=Reference!$D$4, Reference!$E$4, IF(AE16>=Reference!$D$5, Reference!$E$5, "")))) -> Medium | S16: Mitigation | T16: Certificate-based authentication (ETSI TS 103 097) Plausibility checks: e.g., does "RSU" have a fixed position and no dynamics? Logging sudden station type changes and linking to system alerts. | U16: CAM CA service (generation logic) ITS-S security credential provisioning RSU/V2X trust policies in receivers | V16: Altering the StationType misleads ITS-S nodes into applying incorrect trust models, which may suppress scrutiny, prioritize malicious traffic, or trigger traffic adaptations based on false roles (e.g., route clearance for "emergency vehicle"). | W16: G2: Message Integrity G4: Source Authentication G6: Message Freshness (indirectly if trust assumptions delay validation or revoke logic) | Y16: =IF(H16=Reference!$A$12, Reference!$C$12, IF(H16=Reference!$A$11, Reference!$C$11, IF(H16=Reference!$A$10, Reference!$C$10, IF(H16=Reference!$A$9, Reference!$C$9, 0)))) -> 4 | Z16: =IF(J16=Reference!$A$20, Reference!$C$20, IF(J16=Reference!$A$19, Reference!$C$19, IF(J16=Reference!$A$18, Reference!$C$18, IF(J16=Reference!$A$17, Reference!$C$17, 0)))) -> 4 | AA16: =IF(L16=Reference!$A$28, Reference!$C$28, IF(L16=Reference!$A$27, Reference!$C$27, IF(L16=Reference!$A$26, Reference!$C$26, IF(L16=Reference!$A$25, Reference!$C$25, 0)))) -> 7 | AB16: =IF(N16=Reference!$A$36, Reference!$C$36, IF(N16=Reference!$A$35, Reference!$C$35, IF(N16=Reference!$A$34, Reference!$C$34, IF(N16=Reference!$A$33, Reference!$C$33, 0)))) -> 4 | AC16: =(Reference!$B$2*Y16 + Reference!$B$3*AA16 + Reference!$B$4*Z16 + Reference!$B$5 * AB16)/4 -> 7.5 | AD16: =IF(Q16=Reference!$C$41, Reference!$D$41, IF(Q16=Reference!$C$42, Reference!$D$42, IF(Q16=Reference!$C$43, Reference!$D$43, IF(Q16=Reference!$C$44, Reference!$D$44, 0)))) -> 4 | AE16: =1 + (AC16 * AD16) -> 31
B17: Repudiation | C17: Integrity | D17: The attacker intentionally alters the Station Type field within the Basic Container of the CAM message, switching it between valid types (e.g., from personal vehicle to public transport or infrastructure unit). This manipulation can be used to bypass access controls, filtering, or prioritization mechanisms in receiving ITS-S nodes or RSUs, allowing malicious data to be accepted or propagated. | E17: The attacker, having access to the ITS-S stack (via software exploit or unauthorized configuration), modifies the Station Type field during CAM composition. CAMs are then periodically sent via standard CA service routines, but now with misleading identity type, triggering wrong trust assumptions. | F17: Adjacent | G17: The attacker might spoof messages via another nearby device that broadcasts falsified Station Type. | H17: Moderate | I17: A spoofed station type could cause traffic to respond inappropriately (e.g., yielding to a fake emergency vehicle or treating a malicious node as an RSU), potentially causing unsafe behavior. | J17: Moderate | K17: Minimal direct financial damage unless used as part of broader attack (e.g., toll evasion or infrastructure abuse). | L17: Major | M17: Disrupts traffic flow logic, network prioritization, and service-specific policies (e.g., rerouting, prioritization). | N17: Moderate | O17: Misuse of station identity can breach regulatory compliance (e.g., impersonating emergency vehicles) and may expose legal liability to OEMs or operators. | P17: =IF(AC17>=Reference!$H$2, Reference!$G$2, IF(AC17>=Reference!$H$3, Reference!$G$3, IF(AC17>=Reference!$H$4, Reference!$G$4, IF(AC17>=Reference!$H$5, Reference!$G$5, "")))) -> Major | Q17: =IF(F17="Physical", "Very Low", IF(F17="Local", "Low", IF(F17="Adjacent", "Medium", IF(F17="Network", "High", "")))) -> Medium | R17: =IF(AE17>=Reference!$D$2, Reference!$G$2, IF(AE17>=Reference!$D$3, Reference!$E$3, IF(AE17>=Reference!$D$4, Reference!$E$4, IF(AE17>=Reference!$D$5, Reference!$E$5, "")))) -> High | S17: Mitigation | T17: Certificate-based authentication (ETSI TS 103 097) Plausibility checks: e.g., does "RSU" have a fixed position and no dynamics? Logging sudden station type changes and linking to system alerts. | U17: CAM CA service (generation logic) ITS-S security credential provisioning RSU/V2X trust policies in receivers | V17: Altering the StationType misleads ITS-S nodes into applying incorrect trust models, which may suppress scrutiny, prioritize malicious traffic, or trigger traffic adaptations based on false roles (e.g., route clearance for "emergency vehicle"). | W17: G2: Message Integrity G4: Source Authentication G6: Message Freshness (indirectly if trust assumptions delay validation or revoke logic) | Y17: =IF(H17=Reference!$A$12, Reference!$C$12, IF(H17=Reference!$A$11, Reference!$C$11, IF(H17=Reference!$A$10, Reference!$C$10, IF(H17=Reference!$A$9, Reference!$C$9, 0)))) -> 4 | Z17: =IF(J17=Reference!$A$20, Reference!$C$20, IF(J17=Reference!$A$19, Reference!$C$19, IF(J17=Reference!$A$18, Reference!$C$18, IF(J17=Reference!$A$17, Reference!$C$17, 0)))) -> 4 | AA17: =IF(L17=Reference!$A$28, Reference!$C$28, IF(L17=Reference!$A$27, Reference!$C$27, IF(L17=Reference!$A$26, Reference!$C$26, IF(L17=Reference!$A$25, Reference!$C$25, 0)))) -> 7 | AB17: =IF(N17=Reference!$A$36, Reference!$C$36, IF(N17=Reference!$A$35, Reference!$C$35, IF(N17=Reference!$A$34, Reference!$C$34, IF(N17=Reference!$A$33, Reference!$C$33, 0)))) -> 4 | AC17: =(Reference!$B$2*Y17 + Reference!$B$3*AA17 + Reference!$B$4*Z17 + Reference!$B$5 * AB17)/4 -> 7.5 | AD17: =IF(Q17=Reference!$C$41, Reference!$D$41, IF(Q17=Reference!$C$42, Reference!$D$42, IF(Q17=Reference!$C$43, Reference!$D$43, IF(Q17=Reference!$C$44, Reference!$D$44, 0)))) -> 7 | AE17: =1 + (AC17 * AD17) -> 53.5
A18: Low Frequency (LF) Container in CAM messages | B18: Tampering | C18: Integrity | D18: An attacker modifies or injects false location data for roadworks in CAM messages, misinforming nearby vehicles and traffic systems. | E18: Through Compromised RSU or OBU Transmitting CAMs | F18: Network | G18: The tampered location data is transmitted through compromised CAM messages over the V2X network, impacting vehicles and road infrastructure systems. | H18: Major | I18: Incorrect roadwork warnings could cause vehicles to take unsafe detours, enter restricted zones, or collide with obstacles. | J18: Major | K18: Financial losses due to damaged vehicles, delayed deliveries, road repair expenses, and potential legal claims against road authorities. | L18: Major | M18: Misallocation of traffic could lead to temporary congestion and traffic flow disruption, but these impacts may be localized unless widely exploited. | N18: Moderate | O18: Minor privacy concerns, but regulatory liabilities may arise if tampered warnings lead to accidents or road damage. | P18: =IF(AC18>=Reference!$H$2, Reference!$G$2, IF(AC18>=Reference!$H$3, Reference!$G$3, IF(AC18>=Reference!$H$4, Reference!$G$4, IF(AC18>=Reference!$H$5, Reference!$G$5, "")))) -> Severe | Q18: =IF(F18="Physical", "Very Low", IF(F18="Local", "Low", IF(F18="Adjacent", "Medium", IF(F18="Network", "High", "")))) -> High | R18: =IF(AE18>=Reference!$D$2, Reference!$G$2, IF(AE18>=Reference!$D$3, Reference!$E$3, IF(AE18>=Reference!$D$4, Reference!$E$4, IF(AE18>=Reference!$D$5, Reference!$E$5, "")))) -> Severe | S18: Mitigation | T18: Digital Signatures and Message Authentication,Cross-Validation of Location Data,Traffic Camera or Lidar Integration | U18: Low Frequency (LF) Container (Location Data),Traffic Management Systems,V2X Message Integrity Verification,Navigation and Route Planning Systems | V18: Best approach, involving digital signatures, GPS-based validation, and anomaly detection. | Y18: =IF(H18=Reference!$A$12, Reference!$C$12, IF(H18=Reference!$A$11, Reference!$C$11, IF(H18=Reference!$A$10, Reference!$C$10, IF(H18=Reference!$A$9, Reference!$C$9, 0)))) -> 7 | Z18: =IF(J18=Reference!$A$20, Reference!$C$20, IF(J18=Reference!$A$19, Reference!$C$19, IF(J18=Reference!$A$18, Reference!$C$18, IF(J18=Reference!$A$17, Reference!$C$17, 0)))) -> 7 | AA18: =IF(L18=Reference!$A$28, Reference!$C$28, IF(L18=Reference!$A$27, Reference!$C$27, IF(L18=Reference!$A$26, Reference!$C$26, IF(L18=Reference!$A$25, Reference!$C$25, 0)))) -> 7 | AB18: =IF(N18=Reference!$A$36, Reference!$C$36, IF(N18=Reference!$A$35, Reference!$C$35, IF(N18=Reference!$A$34, Reference!$C$34, IF(N18=Reference!$A$33, Reference!$C$33, 0)))) -> 4 | AC18: =(Reference!$B$2*Y18 + Reference!$B$3*AA18 + Reference!$B$4*Z18 + Reference!$B$5 * AB18)/4 -> 11.625 | AD18: =IF(Q18=Reference!$C$41, Reference!$D$41, IF(Q18=Reference!$C$42, Reference!$D$42, IF(Q18=Reference!$C$43, Reference!$D$43, IF(Q18=Reference!$C$44, Reference!$D$44, 0)))) -> 10 | AE18: =1 + (AC18 * AD18) -> 117.25
A19: HF Container in CAM Messages | B19: Tampering | C19: Integrity | D19: The attacker modifies the speed or position data in the CAM messages of the lead or following vehicle in the platoon, causing incorrect decisions regarding following distance and braking. | E19: Through Compromised OBU or V2X Network Injection | F19: Network | G19: The tampered speed or position values are transmitted via compromised CAM messages over the V2X network, impacting multiple vehicles in the platoon. | H19: Severe | I19: Incorrect speed or following distance could lead to rear-end collisions, potentially involving multiple vehicles. The threat is especially critical in high-speed platoons, where reaction times are reduced. | J19: Severe | K19: High financial costs due to vehicle damage, logistics delays, and potential legal claims against the platoon operator or OEMs. Multi-vehicle accidents could result in significant repair and insurance claims. | L19: Major | M19: Disruption of platoon operations can lead to traffic congestion and delays in delivery schedules. Recovery and realignment of the platoon could require manual intervention. | N19: Severe | O19: If the tampering results in accidents or near-misses, regulatory investigations could result in legal liability for V2X system operators. OEMs may face privacy and safety-related fines or penalties. | P19: =IF(AC19>=Reference!$H$2, Reference!$G$2, IF(AC19>=Reference!$H$3, Reference!$G$3, IF(AC19>=Reference!$H$4, Reference!$G$4, IF(AC19>=Reference!$H$5, Reference!$G$5, "")))) -> Severe | Q19: =IF(F19="Physical", "Very Low", IF(F19="Local", "Low", IF(F19="Adjacent", "Medium", IF(F19="Network", "High", "")))) -> High | R19: =IF(AE19>=Reference!$D$2, Reference!$G$2, IF(AE19>=Reference!$D$3, Reference!$E$3, IF(AE19>=Reference!$D$4, Reference!$E$4, IF(AE19>=Reference!$D$5, Reference!$E$5, "")))) -> Severe | S19: Mitigation | T19: Digital Signatures and Message Authentication,Cross-Validation with Onboard Sensors,Anomaly Detection Systems,Adaptive Following Distance Control,SSP-Based Permissions | U19: High Frequency (HF) Container (Speed & Position Data),V2X Communication Protocols ,Platoon Control Systems,Distance Monitoring Systems | V19: Best approach, involving strong cryptographic protections and anomaly detection mechanisms. | Y19: =IF(H19=Reference!$A$12, Reference!$C$12, IF(H19=Reference!$A$11, Reference!$C$11, IF(H19=Reference!$A$10, Reference!$C$10, IF(H19=Reference!$A$9, Reference!$C$9, 0)))) -> 10 | Z19: =IF(J19=Reference!$A$20, Reference!$C$20, IF(J19=Reference!$A$19, Reference!$C$19, IF(J19=Reference!$A$18, Reference!$C$18, IF(J19=Reference!$A$17, Reference!$C$17, 0)))) -> 10 | AA19: =IF(L19=Reference!$A$28, Reference!$C$28, IF(L19=Reference!$A$27, Reference!$C$27, IF(L19=Reference!$A$26, Reference!$C$26, IF(L19=Reference!$A$25, Reference!$C$25, 0)))) -> 7 | AB19: =IF(N19=Reference!$A$36, Reference!$C$36, IF(N19=Reference!$A$35, Reference!$C$35, IF(N19=Reference!$A$34, Reference!$C$34, IF(N19=Reference!$A$33, Reference!$C$33, 0)))) -> 10 | AC19: =(Reference!$B$2*Y19 + Reference!$B$3*AA19 + Reference!$B$4*Z19 + Reference!$B$5 * AB19)/4 -> 16.125 | AD19: =IF(Q19=Reference!$C$41, Reference!$D$41, IF(Q19=Reference!$C$42, Reference!$D$42, IF(Q19=Reference!$C$43, Reference!$D$43, IF(Q19=Reference!$C$44, Reference!$D$44, 0)))) -> 10 | AE19: =1 + (AC19 * AD19) -> 162.25
