Workbook

Sheet TARA strict intersection
A1: Asset | B1: Threat type | C1: Security Attribute | D1: Damage Scenario | E1: Attack Path | F1: Attack vector | G1: Attack Vector Note / Motiv | H1: Safety Impact | I1: Safety Note / Motiv | J1: Financial Impact | K1: Financial Note / Motiv | L1: Operational Impact | M1: Operational Note / Motiv | N1: Privacy and Legislative Impact | O1: Privacy Note / Motiv | P1: Severity Level | Q1: Feasibility Level | R1: Risk Value | S1: Treatment Options | T1: Measures | U1: Affected Design Elements | V1: Justification (Treatment) | W1: Cybersecurity Goals | X1: Medini threat ID | Y1: s | Z1: f | AA1: o | AB1: p | AC1: impact | AD1: feasibility val | AE1: Risk score | AF1: Theme, agreement and source
A2: 1. Cameras (mono + stereo) | B2: Spoofing | C2: Authenticity | D2: Fabricated or replayed images reach the detection pipeline, either through a forged stream injected on the camera link or through a rogue camera node, so the system perceives an accident that does not exist or fails to see a real one. | E2: The attacker reaches the camera link on the roadside network, for example through the camera management interface or a network tap, and replaces the stream sent to the computing unit. | F2: Adjacent | G2: The camera stream travels on the roadside network segment; the attacker needs a foothold there, not physical access to the optics. | H2: Major | I2: A fabricated accident triggers unnecessary emergency braking; a suppressed real accident removes the warning that should prevent a secondary collision (S2). | J2: Moderate | K2: Investigation and remediation costs; liability only if a collision follows. | L2: Major | M2: The perception input of the whole chain is untrusted, so every warning from this station must be questioned. | N2: Negligible | O2: The injected stream itself contains no personal data of real road users. | P2: =IF(AC2>=Reference!$H$2, Reference!$G$2, IF(AC2>=Reference!$H$3, Reference!$G$3, IF(AC2>=Reference!$H$4, Reference!$G$4, IF(AC2>=Reference!$H$5, Reference!$G$5, "")))) -> Severe | Q2: =IF(F2="Physical", "Very Low", IF(F2="Local", "Low", IF(F2="Adjacent", "Medium", IF(F2="Network", "High", "")))) -> Medium | R2: =IF(AE2>=Reference!$D$2, Reference!$E$2, IF(AE2>=Reference!$D$3, Reference!$E$3, IF(AE2>=Reference!$D$4, Reference!$E$4, IF(AE2>=Reference!$D$5, Reference!$E$5, "")))) -> High | S2: Mitigation | T2: Authenticate and encrypt the camera stream (for example RTSP over TLS with client certificates), segment the camera VLAN, monitor stream continuity and timestamps, detect frozen or repeated frames. | U2: Cameras, roadside network, computing unit input stage (Steps 1-2). | V2: The detection chain trusts its sensor input implicitly; without stream authentication every downstream control can be bypassed at the source. | W2: Authenticity, Integrity. | X2: T004 | Y2: =IF(H2=Reference!$A$12, Reference!$C$12, IF(H2=Reference!$A$11, Reference!$C$11, IF(H2=Reference!$A$10, Reference!$C$10, IF(H2=Reference!$A$9, Reference!$C$9, 0)))) -> 7 | Z2: =IF(J2=Reference!$A$20, Reference!$C$20, IF(J2=Reference!$A$19, Reference!$C$19, IF(J2=Reference!$A$18, Reference!$C$18, IF(J2=Reference!$A$17, Reference!$C$17, 0)))) -> 4 | AA2: =IF(L2=Reference!$A$28, Reference!$C$28, IF(L2=Reference!$A$27, Reference!$C$27, IF(L2=Reference!$A$26, Reference!$C$26, IF(L2=Reference!$A$25, Reference!$C$25, 0)))) -> 7 | AB2: =IF(N2=Reference!$A$36, Reference!$C$36, IF(N2=Reference!$A$35, Reference!$C$35, IF(N2=Reference!$A$34, Reference!$C$34, IF(N2=Reference!$A$33, Reference!$C$33, 0)))) -> 1 | AC2: =(Reference!$B$2*Y2 + Reference!$B$3*AA2 + Reference!$B$4*Z2 + Reference!$B$5 * AB2)/4 -> 11.0625 | AD2: =IF(Q2=Reference!$C$41, Reference!$D$41, IF(Q2=Reference!$C$42, Reference!$D$42, IF(Q2=Reference!$C$43, Reference!$D$43, IF(Q2=Reference!$C$44, Reference!$D$44, 0)))) -> 7 | AE2: =1 + (AC2 * AD2) -> 78.4375 | AF2: Raised by all six model outputs; medini T004 (Mono + Stereo | Spoofing); copied from row 9 of the full analysis
A3: 1. Cameras (mono + stereo) | B3: Tampering | C3: Integrity | D3: The camera is re-aimed, or its stored position and orientation are changed, so the event location computed for the DENM no longer matches reality and warnings are sent for the wrong road section. | E3: Physical access to the pole, or modification of the camera configuration stored on the computing unit. | F3: Physical | G3: Turning the camera requires presence at the installation; the configuration variant would be Adjacent. | H3: Major | I3: Drivers are warned about a hazard at a place where there is none, and the real hazard stays unannounced (S2). | J3: Moderate | K3: Site visit, recalibration and investigation. | L3: Major | M3: Every warning from this station points at the wrong location until the pose is restored. | N3: Negligible | O3: No personal data is affected. | P3: =IF(AC3>=Reference!$H$2, Reference!$G$2, IF(AC3>=Reference!$H$3, Reference!$G$3, IF(AC3>=Reference!$H$4, Reference!$G$4, IF(AC3>=Reference!$H$5, Reference!$G$5, "")))) -> Severe | Q3: =IF(F3="Physical", "Very Low", IF(F3="Local", "Low", IF(F3="Adjacent", "Medium", IF(F3="Network", "High", "")))) -> Very Low | R3: =IF(AE3>=Reference!$D$2, Reference!$E$2, IF(AE3>=Reference!$D$3, Reference!$E$3, IF(AE3>=Reference!$D$4, Reference!$E$4, IF(AE3>=Reference!$D$5, Reference!$E$5, "")))) -> Low | S3: Mitigation | T3: Tamper-resistant mounting, automatic detection of view changes against a reference image, signed and monitored calibration data, alarm to the operator on deviation. | U3: Camera mounting, calibration data on the computing unit, monitoring. | V3: Cheap for an attacker and easy to miss, because the system keeps producing plausible messages. | W3: Integrity, Authenticity. | X3: T002 | Y3: =IF(H3=Reference!$A$12, Reference!$C$12, IF(H3=Reference!$A$11, Reference!$C$11, IF(H3=Reference!$A$10, Reference!$C$10, IF(H3=Reference!$A$9, Reference!$C$9, 0)))) -> 7 | Z3: =IF(J3=Reference!$A$20, Reference!$C$20, IF(J3=Reference!$A$19, Reference!$C$19, IF(J3=Reference!$A$18, Reference!$C$18, IF(J3=Reference!$A$17, Reference!$C$17, 0)))) -> 4 | AA3: =IF(L3=Reference!$A$28, Reference!$C$28, IF(L3=Reference!$A$27, Reference!$C$27, IF(L3=Reference!$A$26, Reference!$C$26, IF(L3=Reference!$A$25, Reference!$C$25, 0)))) -> 7 | AB3: =IF(N3=Reference!$A$36, Reference!$C$36, IF(N3=Reference!$A$35, Reference!$C$35, IF(N3=Reference!$A$34, Reference!$C$34, IF(N3=Reference!$A$33, Reference!$C$33, 0)))) -> 1 | AC3: =(Reference!$B$2*Y3 + Reference!$B$3*AA3 + Reference!$B$4*Z3 + Reference!$B$5 * AB3)/4 -> 11.0625 | AD3: =IF(Q3=Reference!$C$41, Reference!$D$41, IF(Q3=Reference!$C$42, Reference!$D$42, IF(Q3=Reference!$C$43, Reference!$D$43, IF(Q3=Reference!$C$44, Reference!$D$44, 0)))) -> 1 | AE3: =1 + (AC3 * AD3) -> 12.0625 | AF3: Raised by all six model outputs; medini T002 (Mono + Stereo | Tampering); copied from row 24 of the full analysis
A4: 1. Cameras (mono + stereo) | B4: Denial of service | C4: Availability | D4: The camera is blinded with a laser or strong light, covered, sprayed, misaligned or disconnected, so accidents in its field of view are never detected and no warning is issued. | E4: The attacker reaches the pole or illuminates the camera from the roadside; power or network cables can also be cut. | F4: Physical | G4: Physical presence at the roadside installation is required. | H4: Major | I4: A real accident stays unannounced, so approaching drivers are not warned and secondary collisions are not prevented (S2). | J4: Moderate | K4: Repair or replacement of the unit and a site visit. | L4: Severe | M4: The core function of the roadside station is lost for the affected field of view until the camera is restored. | N4: Negligible | O4: No personal data is disclosed. | P4: =IF(AC4>=Reference!$H$2, Reference!$G$2, IF(AC4>=Reference!$H$3, Reference!$G$3, IF(AC4>=Reference!$H$4, Reference!$G$4, IF(AC4>=Reference!$H$5, Reference!$G$5, "")))) -> Severe | Q4: =IF(F4="Physical", "Very Low", IF(F4="Local", "Low", IF(F4="Adjacent", "Medium", IF(F4="Network", "High", "")))) -> Very Low | R4: =IF(AE4>=Reference!$D$2, Reference!$E$2, IF(AE4>=Reference!$D$3, Reference!$E$3, IF(AE4>=Reference!$D$4, Reference!$E$4, IF(AE4>=Reference!$D$5, Reference!$E$5, "")))) -> Low | S4: Mitigation | T4: Tamper-resistant mounting and housing, monitoring of stream health, brightness and alignment, automatic alarm to the operator when the view changes or the feed stops, redundant camera coverage at critical sites. | U4: Camera hardware and mounting, computing unit health monitoring, operator back-end alerting. | V4: Detection of the failure matters more than prevention: the operator must know that the site is blind. | W4: Availability, Integrity. | X4: T003 | Y4: =IF(H4=Reference!$A$12, Reference!$C$12, IF(H4=Reference!$A$11, Reference!$C$11, IF(H4=Reference!$A$10, Reference!$C$10, IF(H4=Reference!$A$9, Reference!$C$9, 0)))) -> 7 | Z4: =IF(J4=Reference!$A$20, Reference!$C$20, IF(J4=Reference!$A$19, Reference!$C$19, IF(J4=Reference!$A$18, Reference!$C$18, IF(J4=Reference!$A$17, Reference!$C$17, 0)))) -> 4 | AA4: =IF(L4=Reference!$A$28, Reference!$C$28, IF(L4=Reference!$A$27, Reference!$C$27, IF(L4=Reference!$A$26, Reference!$C$26, IF(L4=Reference!$A$25, Reference!$C$25, 0)))) -> 10 | AB4: =IF(N4=Reference!$A$36, Reference!$C$36, IF(N4=Reference!$A$35, Reference!$C$35, IF(N4=Reference!$A$34, Reference!$C$34, IF(N4=Reference!$A$33, Reference!$C$33, 0)))) -> 1 | AC4: =(Reference!$B$2*Y4 + Reference!$B$3*AA4 + Reference!$B$4*Z4 + Reference!$B$5 * AB4)/4 -> 11.8125 | AD4: =IF(Q4=Reference!$C$41, Reference!$D$41, IF(Q4=Reference!$C$42, Reference!$D$42, IF(Q4=Reference!$C$43, Reference!$D$43, IF(Q4=Reference!$C$44, Reference!$D$44, 0)))) -> 1 | AE4: =1 + (AC4 * AD4) -> 12.8125 | AF4: Raised by all six model outputs; medini T003 (Mono + Stereo | Denial of Service); copied from row 14 of the full analysis
A5: 8. DENM encoder (ASN.1 UPER payload) | B5: Tampering | C5: Integrity | D5: The encoder software or its ASN.1 definitions are modified, so the station produces syntactically valid messages whose meaning differs from the detected event. | E5: Access to the computing unit through the roadside network or an unsigned update, followed by modification of the encoder or its schema files. | F5: Adjacent | G5: Access to the roadside network segment or to the update path is required. | H5: Major | I5: Every message of the station carries altered content while appearing correct (S2). | J5: Major | K5: Liability and the effort of verifying all deployed stations. | L5: Severe | M5: The station keeps operating while producing wrong messages, which is harder to detect than an outage. | N5: Negligible | O5: No personal data is affected. | P5: =IF(AC5>=Reference!$H$2, Reference!$G$2, IF(AC5>=Reference!$H$3, Reference!$G$3, IF(AC5>=Reference!$H$4, Reference!$G$4, IF(AC5>=Reference!$H$5, Reference!$G$5, "")))) -> Severe | Q5: =IF(F5="Physical", "Very Low", IF(F5="Local", "Low", IF(F5="Adjacent", "Medium", IF(F5="Network", "High", "")))) -> Medium | R5: =IF(AE5>=Reference!$D$2, Reference!$E$2, IF(AE5>=Reference!$D$3, Reference!$E$3, IF(AE5>=Reference!$D$4, Reference!$E$4, IF(AE5>=Reference!$D$5, Reference!$E$5, "")))) -> High | S5: Mitigation | T5: Signed software and schema files, integrity verification at start-up, read-only deployment, comparison of encoded output against the agent output before signing. | U5: Computing unit software, ASN.1 schema files, update pipeline (Step 8). | V5: Together with the model file row, this covers the software supply chain of the roadside station. | W5: Integrity, Authenticity. | X5: T098 | Y5: =IF(H5=Reference!$A$12, Reference!$C$12, IF(H5=Reference!$A$11, Reference!$C$11, IF(H5=Reference!$A$10, Reference!$C$10, IF(H5=Reference!$A$9, Reference!$C$9, 0)))) -> 7 | Z5: =IF(J5=Reference!$A$20, Reference!$C$20, IF(J5=Reference!$A$19, Reference!$C$19, IF(J5=Reference!$A$18, Reference!$C$18, IF(J5=Reference!$A$17, Reference!$C$17, 0)))) -> 7 | AA5: =IF(L5=Reference!$A$28, Reference!$C$28, IF(L5=Reference!$A$27, Reference!$C$27, IF(L5=Reference!$A$26, Reference!$C$26, IF(L5=Reference!$A$25, Reference!$C$25, 0)))) -> 10 | AB5: =IF(N5=Reference!$A$36, Reference!$C$36, IF(N5=Reference!$A$35, Reference!$C$35, IF(N5=Reference!$A$34, Reference!$C$34, IF(N5=Reference!$A$33, Reference!$C$33, 0)))) -> 1 | AC5: =(Reference!$B$2*Y5 + Reference!$B$3*AA5 + Reference!$B$4*Z5 + Reference!$B$5 * AB5)/4 -> 12.1875 | AD5: =IF(Q5=Reference!$C$41, Reference!$D$41, IF(Q5=Reference!$C$42, Reference!$D$42, IF(Q5=Reference!$C$43, Reference!$D$43, IF(Q5=Reference!$C$44, Reference!$D$44, 0)))) -> 7 | AE5: =1 + (AC5 * AD5) -> 86.3125 | AF5: Raised by all six model outputs; medini T098 (ASN.1 UPER payload | Tampering); copied from row 29 of the full analysis
A6: 9. RSU (PC5 radio, signing keys in HSM) | B6: Spoofing | C6: Authenticity | D6: A rogue roadside device broadcasts DENMs that claim to originate from the legitimate RSU, announcing an accident that does not exist or cancelling a real one. Every vehicle in radio range shows a false hazard warning to the driver. | E6: The attacker operates a C-V2X radio inside the coverage area and either holds valid ITS credentials (stolen, extracted or issued to a rogue node) or exploits receivers that do not verify message signatures. | F6: Network | G6: The attack is carried out over the PC5 sidelink; no physical access to the roadside station is needed, only presence in the radio coverage area. | H6: Major | I6: A false accident warning at motorway speed can trigger hard braking and rear-end collisions; injuries are severe but survival is probable (S2). | J6: Major | K6: Liability claims after a provoked collision, incident response costs and possible suspension of the warning service in the affected area. | L6: Major | M6: The hazard warning function becomes untrustworthy and the operator may have to disable it locally until the source is identified. | N6: Negligible | O6: The forged message carries no personal data of road users. | P6: =IF(AC6>=Reference!$H$2, Reference!$G$2, IF(AC6>=Reference!$H$3, Reference!$G$3, IF(AC6>=Reference!$H$4, Reference!$G$4, IF(AC6>=Reference!$H$5, Reference!$G$5, "")))) -> Severe | Q6: =IF(F6="Physical", "Very Low", IF(F6="Local", "Low", IF(F6="Adjacent", "Medium", IF(F6="Network", "High", "")))) -> High | R6: =IF(AE6>=Reference!$D$2, Reference!$E$2, IF(AE6>=Reference!$D$3, Reference!$E$3, IF(AE6>=Reference!$D$4, Reference!$E$4, IF(AE6>=Reference!$D$5, Reference!$E$5, "")))) -> Critical | S6: Mitigation | T6: Verify IEEE 1609.2 / ETSI TS 103 097 signatures and certificate permissions in the OBU before a warning is displayed; plausibility and misbehaviour detection (position, cause code, event history); revocation of misbehaving certificates. | U6: RSU signing chain, OBU verification stack, PKI trust list, vehicle warning logic (Step 12). | V6: The scenario cannot be avoided, because receiving DENMs is the purpose of the function; mitigation through authentication and misbehaviour detection is the only practical option. | W6: Authenticity, Integrity, Non-repudiation. | X6: T115 | Y6: =IF(H6=Reference!$A$12, Reference!$C$12, IF(H6=Reference!$A$11, Reference!$C$11, IF(H6=Reference!$A$10, Reference!$C$10, IF(H6=Reference!$A$9, Reference!$C$9, 0)))) -> 7 | Z6: =IF(J6=Reference!$A$20, Reference!$C$20, IF(J6=Reference!$A$19, Reference!$C$19, IF(J6=Reference!$A$18, Reference!$C$18, IF(J6=Reference!$A$17, Reference!$C$17, 0)))) -> 7 | AA6: =IF(L6=Reference!$A$28, Reference!$C$28, IF(L6=Reference!$A$27, Reference!$C$27, IF(L6=Reference!$A$26, Reference!$C$26, IF(L6=Reference!$A$25, Reference!$C$25, 0)))) -> 7 | AB6: =IF(N6=Reference!$A$36, Reference!$C$36, IF(N6=Reference!$A$35, Reference!$C$35, IF(N6=Reference!$A$34, Reference!$C$34, IF(N6=Reference!$A$33, Reference!$C$33, 0)))) -> 1 | AC6: =(Reference!$B$2*Y6 + Reference!$B$3*AA6 + Reference!$B$4*Z6 + Reference!$B$5 * AB6)/4 -> 11.4375 | AD6: =IF(Q6=Reference!$C$41, Reference!$D$41, IF(Q6=Reference!$C$42, Reference!$D$42, IF(Q6=Reference!$C$43, Reference!$D$43, IF(Q6=Reference!$C$44, Reference!$D$44, 0)))) -> 10 | AE6: =1 + (AC6 * AD6) -> 115.375 | AF6: Raised by all six model outputs; medini T115 (Signs, PC5, HSM | Spoofing); copied from row 1 of the full analysis
A7: 9. RSU (firmware and configuration) | B7: Tampering | C7: Integrity | D7: The firmware or the configuration of the roadside unit is modified, so it alters, drops or re-orders the messages it signs and broadcasts while continuing to appear operational. | E7: Access to the management interface of the unit over the operator network, using default or weak credentials, or an unsigned firmware update. | F7: Network | G7: The management services of the unit are reachable over the network; no physical access is required. | H7: Major | I7: The content broadcast to every vehicle in range no longer corresponds to the detected event (S2). | J7: Major | K7: Liability for a resulting collision and verification of every deployed unit. | L7: Severe | M7: The station keeps running while producing manipulated output, which is harder to detect than an outage. | N7: Negligible | O7: No personal data is affected. | P7: =IF(AC7>=Reference!$H$2, Reference!$G$2, IF(AC7>=Reference!$H$3, Reference!$G$3, IF(AC7>=Reference!$H$4, Reference!$G$4, IF(AC7>=Reference!$H$5, Reference!$G$5, "")))) -> Severe | Q7: =IF(F7="Physical", "Very Low", IF(F7="Local", "Low", IF(F7="Adjacent", "Medium", IF(F7="Network", "High", "")))) -> High | R7: =IF(AE7>=Reference!$D$2, Reference!$E$2, IF(AE7>=Reference!$D$3, Reference!$E$3, IF(AE7>=Reference!$D$4, Reference!$E$4, IF(AE7>=Reference!$D$5, Reference!$E$5, "")))) -> Critical | S7: Mitigation | T7: Signed firmware and configuration, secure boot, removal of default credentials, management access only from a dedicated network, integrity monitoring and alerting on configuration change. | U7: RSU firmware and configuration, operator management network, update process (Step 9). | V7: Distinct from the privilege escalation row: here the unit is reconfigured, there the attacker uses its signing key directly. | W7: Integrity, Authenticity. | X7: T113 | Y7: =IF(H7=Reference!$A$12, Reference!$C$12, IF(H7=Reference!$A$11, Reference!$C$11, IF(H7=Reference!$A$10, Reference!$C$10, IF(H7=Reference!$A$9, Reference!$C$9, 0)))) -> 7 | Z7: =IF(J7=Reference!$A$20, Reference!$C$20, IF(J7=Reference!$A$19, Reference!$C$19, IF(J7=Reference!$A$18, Reference!$C$18, IF(J7=Reference!$A$17, Reference!$C$17, 0)))) -> 7 | AA7: =IF(L7=Reference!$A$28, Reference!$C$28, IF(L7=Reference!$A$27, Reference!$C$27, IF(L7=Reference!$A$26, Reference!$C$26, IF(L7=Reference!$A$25, Reference!$C$25, 0)))) -> 10 | AB7: =IF(N7=Reference!$A$36, Reference!$C$36, IF(N7=Reference!$A$35, Reference!$C$35, IF(N7=Reference!$A$34, Reference!$C$34, IF(N7=Reference!$A$33, Reference!$C$33, 0)))) -> 1 | AC7: =(Reference!$B$2*Y7 + Reference!$B$3*AA7 + Reference!$B$4*Z7 + Reference!$B$5 * AB7)/4 -> 12.1875 | AD7: =IF(Q7=Reference!$C$41, Reference!$D$41, IF(Q7=Reference!$C$42, Reference!$D$42, IF(Q7=Reference!$C$43, Reference!$D$43, IF(Q7=Reference!$C$44, Reference!$D$44, 0)))) -> 10 | AE7: =1 + (AC7 * AD7) -> 122.875 | AF7: Raised by all six model outputs; medini T113 (Signs, PC5, HSM | Tampering); written for this sheet
A8: 9. RSU signing keys (HSM) | B8: Information disclosure | C8: Confidentiality | D8: The private signing key of the RSU is extracted, for example because it is generated or stored outside the security module or through a physical side-channel attack, after which the attacker can sign forged DENMs indefinitely. | E8: Physical access to the pole-mounted RSU or to a decommissioned unit, combined with a misconfiguration that keeps key material outside the FIPS 140-2 level 3 module. | F8: Physical | G8: The attack path requires physical possession of, or direct access to, the roadside unit. | H8: Major | I8: The stolen key enables forged warnings with valid signatures; the effect equals a rogue RSU broadcast and persists until the certificate is revoked (S2). | J8: Major | K8: Revocation and replacement of the unit, investigation costs and liability if forged warnings were issued. | L8: Major | M8: Until revocation, every message signed with this key must be treated as untrusted. | N8: Negligible | O8: The key material itself exposes no personal data of road users. | P8: =IF(AC8>=Reference!$H$2, Reference!$G$2, IF(AC8>=Reference!$H$3, Reference!$G$3, IF(AC8>=Reference!$H$4, Reference!$G$4, IF(AC8>=Reference!$H$5, Reference!$G$5, "")))) -> Severe | Q8: =IF(F8="Physical", "Very Low", IF(F8="Local", "Low", IF(F8="Adjacent", "Medium", IF(F8="Network", "High", "")))) -> Very Low | R8: =IF(AE8>=Reference!$D$2, Reference!$E$2, IF(AE8>=Reference!$D$3, Reference!$E$3, IF(AE8>=Reference!$D$4, Reference!$E$4, IF(AE8>=Reference!$D$5, Reference!$E$5, "")))) -> Low | S8: Mitigation | T8: Generate and keep keys inside the HSM, enable tamper detection and zeroisation, physically secure the cabinet, monitor enclosure opening, revoke certificates as soon as tampering is detected. | U8: RSU hardware, HSM configuration, key management procedures, revocation service. | V8: Feasibility is low because physical access is required, which is why the risk value stays below the network-based rows even though the impact is comparable. | W8: Confidentiality, Authenticity, Integrity. | X8: T112 | Y8: =IF(H8=Reference!$A$12, Reference!$C$12, IF(H8=Reference!$A$11, Reference!$C$11, IF(H8=Reference!$A$10, Reference!$C$10, IF(H8=Reference!$A$9, Reference!$C$9, 0)))) -> 7 | Z8: =IF(J8=Reference!$A$20, Reference!$C$20, IF(J8=Reference!$A$19, Reference!$C$19, IF(J8=Reference!$A$18, Reference!$C$18, IF(J8=Reference!$A$17, Reference!$C$17, 0)))) -> 7 | AA8: =IF(L8=Reference!$A$28, Reference!$C$28, IF(L8=Reference!$A$27, Reference!$C$27, IF(L8=Reference!$A$26, Reference!$C$26, IF(L8=Reference!$A$25, Reference!$C$25, 0)))) -> 7 | AB8: =IF(N8=Reference!$A$36, Reference!$C$36, IF(N8=Reference!$A$35, Reference!$C$35, IF(N8=Reference!$A$34, Reference!$C$34, IF(N8=Reference!$A$33, Reference!$C$33, 0)))) -> 1 | AC8: =(Reference!$B$2*Y8 + Reference!$B$3*AA8 + Reference!$B$4*Z8 + Reference!$B$5 * AB8)/4 -> 11.4375 | AD8: =IF(Q8=Reference!$C$41, Reference!$D$41, IF(Q8=Reference!$C$42, Reference!$D$42, IF(Q8=Reference!$C$43, Reference!$D$43, IF(Q8=Reference!$C$44, Reference!$D$44, 0)))) -> 1 | AE8: =1 + (AC8 * AD8) -> 12.4375 | AF8: Raised by all six model outputs; medini T112 (Signs, PC5, HSM | Information Disclosure); copied from row 5 of the full analysis
A9: 9 -> 11. PC5 sidelink (RSU to OBU) | B9: Tampering | C9: Integrity | D9: Messages in flight on the sidelink are altered, for example by transmitting a stronger modified copy that overshadows the legitimate one, so vehicles receive different content from what the roadside unit sent. | E9: A C-V2X transmitter inside the coverage area, timed against the legitimate transmission. | F9: Network | G9: The attack is carried out over the air and requires no access to any system. | H9: Major | I9: The altered warning can send drivers the wrong hazard type, position or lane status (S2). | J9: Moderate | K9: Investigation and, for a persistent source, the cost of locating it. | L9: Major | M9: The delivered content of the warning service cannot be trusted in the affected area. | N9: Negligible | O9: No personal data is affected. | P9: =IF(AC9>=Reference!$H$2, Reference!$G$2, IF(AC9>=Reference!$H$3, Reference!$G$3, IF(AC9>=Reference!$H$4, Reference!$G$4, IF(AC9>=Reference!$H$5, Reference!$G$5, "")))) -> Severe | Q9: =IF(F9="Physical", "Very Low", IF(F9="Local", "Low", IF(F9="Adjacent", "Medium", IF(F9="Network", "High", "")))) -> High | R9: =IF(AE9>=Reference!$D$2, Reference!$E$2, IF(AE9>=Reference!$D$3, Reference!$E$3, IF(AE9>=Reference!$D$4, Reference!$E$4, IF(AE9>=Reference!$D$5, Reference!$E$5, "")))) -> Critical | S9: Mitigation | T9: Verify the message signature in the vehicle before use, reject messages that fail verification, detect duplicated or conflicting messages for the same event, monitor the channel for anomalies. | U9: RSU radio, PC5 channel, OBU verification stack (Steps 9-11). | V9: Message signing already prevents the altered copy from being accepted, provided the vehicle actually verifies it. | W9: Integrity, Authenticity. | X9: T131 | Y9: =IF(H9=Reference!$A$12, Reference!$C$12, IF(H9=Reference!$A$11, Reference!$C$11, IF(H9=Reference!$A$10, Reference!$C$10, IF(H9=Reference!$A$9, Reference!$C$9, 0)))) -> 7 | Z9: =IF(J9=Reference!$A$20, Reference!$C$20, IF(J9=Reference!$A$19, Reference!$C$19, IF(J9=Reference!$A$18, Reference!$C$18, IF(J9=Reference!$A$17, Reference!$C$17, 0)))) -> 4 | AA9: =IF(L9=Reference!$A$28, Reference!$C$28, IF(L9=Reference!$A$27, Reference!$C$27, IF(L9=Reference!$A$26, Reference!$C$26, IF(L9=Reference!$A$25, Reference!$C$25, 0)))) -> 7 | AB9: =IF(N9=Reference!$A$36, Reference!$C$36, IF(N9=Reference!$A$35, Reference!$C$35, IF(N9=Reference!$A$34, Reference!$C$34, IF(N9=Reference!$A$33, Reference!$C$33, 0)))) -> 1 | AC9: =(Reference!$B$2*Y9 + Reference!$B$3*AA9 + Reference!$B$4*Z9 + Reference!$B$5 * AB9)/4 -> 11.0625 | AD9: =IF(Q9=Reference!$C$41, Reference!$D$41, IF(Q9=Reference!$C$42, Reference!$D$42, IF(Q9=Reference!$C$43, Reference!$D$43, IF(Q9=Reference!$C$44, Reference!$D$44, 0)))) -> 10 | AE9: =1 + (AC9 * AD9) -> 111.625 | AF9: Raised by all six model outputs; medini T131 (pc5_out ↔ pc5_in | Tampering); written for this sheet
A10: 9 -> 11. PC5 sidelink (RSU to OBU) | B10: Denial of service | C10: Availability | D10: The 5.9 GHz channel is jammed, or flooded with valid-format messages, so vehicles in the area do not receive the hazard warning even though the roadside station generated it correctly. | E10: The attacker operates a jammer or a C-V2X transmitter inside the coverage area of the roadside unit. | F10: Network | G10: The attack is carried out over the air inside the radio coverage area and needs no access to any system. | H10: Major | I10: The warning does not reach the driver at the moment it is needed, so a secondary collision is not prevented (S2). | J10: Moderate | K10: Investigation and, if the jamming is persistent, the cost of locating and removing the source. | L10: Severe | M10: The delivery path of the warning is lost; the function fails exactly where it is needed. | N10: Negligible | O10: No personal data is affected. | P10: =IF(AC10>=Reference!$H$2, Reference!$G$2, IF(AC10>=Reference!$H$3, Reference!$G$3, IF(AC10>=Reference!$H$4, Reference!$G$4, IF(AC10>=Reference!$H$5, Reference!$G$5, "")))) -> Severe | Q10: =IF(F10="Physical", "Very Low", IF(F10="Local", "Low", IF(F10="Adjacent", "Medium", IF(F10="Network", "High", "")))) -> High | R10: =IF(AE10>=Reference!$D$2, Reference!$E$2, IF(AE10>=Reference!$D$3, Reference!$E$3, IF(AE10>=Reference!$D$4, Reference!$E$4, IF(AE10>=Reference!$D$5, Reference!$E$5, "")))) -> Critical | S10: Mitigation | T10: Detect and report abnormal channel occupancy and message loss to the operator, use the cellular V2N path as an independent delivery route, apply congestion control and message filtering at the receiver, locate persistent jammers with the operator and the regulator. | U10: RSU radio, OBU radio, central ITS-S V2N path, monitoring. | V10: Jamming cannot be prevented on a shared radio channel; the treatment is detection plus an independent delivery path, which the architecture already provides through V2N. | W10: Availability. | X10: T132 | Y10: =IF(H10=Reference!$A$12, Reference!$C$12, IF(H10=Reference!$A$11, Reference!$C$11, IF(H10=Reference!$A$10, Reference!$C$10, IF(H10=Reference!$A$9, Reference!$C$9, 0)))) -> 7 | Z10: =IF(J10=Reference!$A$20, Reference!$C$20, IF(J10=Reference!$A$19, Reference!$C$19, IF(J10=Reference!$A$18, Reference!$C$18, IF(J10=Reference!$A$17, Reference!$C$17, 0)))) -> 4 | AA10: =IF(L10=Reference!$A$28, Reference!$C$28, IF(L10=Reference!$A$27, Reference!$C$27, IF(L10=Reference!$A$26, Reference!$C$26, IF(L10=Reference!$A$25, Reference!$C$25, 0)))) -> 10 | AB10: =IF(N10=Reference!$A$36, Reference!$C$36, IF(N10=Reference!$A$35, Reference!$C$35, IF(N10=Reference!$A$34, Reference!$C$34, IF(N10=Reference!$A$33, Reference!$C$33, 0)))) -> 1 | AC10: =(Reference!$B$2*Y10 + Reference!$B$3*AA10 + Reference!$B$4*Z10 + Reference!$B$5 * AB10)/4 -> 11.8125 | AD10: =IF(Q10=Reference!$C$41, Reference!$D$41, IF(Q10=Reference!$C$42, Reference!$D$42, IF(Q10=Reference!$C$43, Reference!$D$43, IF(Q10=Reference!$C$44, Reference!$D$44, 0)))) -> 10 | AE10: =1 + (AC10 * AD10) -> 119.125 | AF10: Raised by all six model outputs; medini T132 (pc5_out ↔ pc5_in | Denial of Service); copied from row 15 of the full analysis
A11: 11. OBU (station identity) | B11: Spoofing | C11: Authenticity | D11: A rogue device presents itself as a legitimate on-board unit towards the roadside unit and the back-end, for example to obtain services, to inject false status information or to appear as several vehicles at once. | E11: Use of stolen or cloned credentials, or exploitation of a back-end interface that does not verify the station identity. | F11: Network | G11: The attack is carried out over the radio and cellular interfaces. | H11: Moderate | I11: In this architecture the vehicle mainly receives, so the direct safety effect is limited; false status can still distort the operator view (S1). | J11: Moderate | K11: Investigation and possible revocation of credentials. | L11: Moderate | M11: Trust in vehicle-provided information is degraded. | N11: Moderate | O11: Cloned identities can be used to observe or impersonate a specific vehicle. | P11: =IF(AC11>=Reference!$H$2, Reference!$G$2, IF(AC11>=Reference!$H$3, Reference!$G$3, IF(AC11>=Reference!$H$4, Reference!$G$4, IF(AC11>=Reference!$H$5, Reference!$G$5, "")))) -> Major | Q11: =IF(F11="Physical", "Very Low", IF(F11="Local", "Low", IF(F11="Adjacent", "Medium", IF(F11="Network", "High", "")))) -> High | R11: =IF(AE11>=Reference!$D$2, Reference!$E$2, IF(AE11>=Reference!$D$3, Reference!$E$3, IF(AE11>=Reference!$D$4, Reference!$E$4, IF(AE11>=Reference!$D$5, Reference!$E$5, "")))) -> High | S11: Mitigation | T11: Verify station certificates and their permissions, detect several stations using the same identity, bind credentials to the hardware security element, revoke on detection. | U11: OBU credentials, RSU and back-end verification, PKI (Steps 10-11). | V11: Lower risk here than in architectures where vehicles also generate warnings, which is worth stating explicitly. | W11: Authenticity. | X11: T142 | Y11: =IF(H11=Reference!$A$12, Reference!$C$12, IF(H11=Reference!$A$11, Reference!$C$11, IF(H11=Reference!$A$10, Reference!$C$10, IF(H11=Reference!$A$9, Reference!$C$9, 0)))) -> 4 | Z11: =IF(J11=Reference!$A$20, Reference!$C$20, IF(J11=Reference!$A$19, Reference!$C$19, IF(J11=Reference!$A$18, Reference!$C$18, IF(J11=Reference!$A$17, Reference!$C$17, 0)))) -> 4 | AA11: =IF(L11=Reference!$A$28, Reference!$C$28, IF(L11=Reference!$A$27, Reference!$C$27, IF(L11=Reference!$A$26, Reference!$C$26, IF(L11=Reference!$A$25, Reference!$C$25, 0)))) -> 4 | AB11: =IF(N11=Reference!$A$36, Reference!$C$36, IF(N11=Reference!$A$35, Reference!$C$35, IF(N11=Reference!$A$34, Reference!$C$34, IF(N11=Reference!$A$33, Reference!$C$33, 0)))) -> 4 | AC11: =(Reference!$B$2*Y11 + Reference!$B$3*AA11 + Reference!$B$4*Z11 + Reference!$B$5 * AB11)/4 -> 6.75 | AD11: =IF(Q11=Reference!$C$41, Reference!$D$41, IF(Q11=Reference!$C$42, Reference!$D$42, IF(Q11=Reference!$C$43, Reference!$D$43, IF(Q11=Reference!$C$44, Reference!$D$44, 0)))) -> 10 | AE11: =1 + (AC11 * AD11) -> 68.5 | AF11: Raised by all six model outputs; medini T142 (PC5 + Uumodem | Spoofing); copied from row 40 of the full analysis
A12: 11. OBU (V2X stack and ASN.1 decoder) | B12: Denial of service | C12: Availability | D12: Malformed or out-of-range DENM fields crash the receiving V2X stack or its ASN.1 decoder, so the vehicle stops processing warnings; a memory corruption in the decoder could also lead to code execution. | E12: The attacker broadcasts crafted messages on PC5, or the malformed content originates from the unvalidated model output of the roadside station itself. | F12: Network | G12: The messages are received over the air by every vehicle in range. | H12: Major | I12: A vehicle that stops processing V2X messages receives no further warnings; a code execution variant would raise this to the level of the previous row (S2). | J12: Moderate | K12: Software correction and field campaign for the affected units. | L12: Severe | M12: Loss of the reception function in every vehicle exposed to the message. | N12: Negligible | O12: No personal data is affected. | P12: =IF(AC12>=Reference!$H$2, Reference!$G$2, IF(AC12>=Reference!$H$3, Reference!$G$3, IF(AC12>=Reference!$H$4, Reference!$G$4, IF(AC12>=Reference!$H$5, Reference!$G$5, "")))) -> Severe | Q12: =IF(F12="Physical", "Very Low", IF(F12="Local", "Low", IF(F12="Adjacent", "Medium", IF(F12="Network", "High", "")))) -> High | R12: =IF(AE12>=Reference!$D$2, Reference!$E$2, IF(AE12>=Reference!$D$3, Reference!$E$3, IF(AE12>=Reference!$D$4, Reference!$E$4, IF(AE12>=Reference!$D$5, Reference!$E$5, "")))) -> Critical | S12: Mitigation | T12: Validate the DENM against the ASN.1 schema and plausibility rules before signing at the roadside, fuzz-test the receiving stack, apply memory-safe decoding, isolate the parser process, rate-limit malformed messages. | U12: DENM encoder (Step 8), OBU V2X stack and decoder (Step 11). | V12: The only row where the roadside station can harm vehicles without any attacker, because the model output is encoded and broadcast without a full validation step. | W12: Availability, Integrity. | X12: T141 | Y12: =IF(H12=Reference!$A$12, Reference!$C$12, IF(H12=Reference!$A$11, Reference!$C$11, IF(H12=Reference!$A$10, Reference!$C$10, IF(H12=Reference!$A$9, Reference!$C$9, 0)))) -> 7 | Z12: =IF(J12=Reference!$A$20, Reference!$C$20, IF(J12=Reference!$A$19, Reference!$C$19, IF(J12=Reference!$A$18, Reference!$C$18, IF(J12=Reference!$A$17, Reference!$C$17, 0)))) -> 4 | AA12: =IF(L12=Reference!$A$28, Reference!$C$28, IF(L12=Reference!$A$27, Reference!$C$27, IF(L12=Reference!$A$26, Reference!$C$26, IF(L12=Reference!$A$25, Reference!$C$25, 0)))) -> 10 | AB12: =IF(N12=Reference!$A$36, Reference!$C$36, IF(N12=Reference!$A$35, Reference!$C$35, IF(N12=Reference!$A$34, Reference!$C$34, IF(N12=Reference!$A$33, Reference!$C$33, 0)))) -> 1 | AC12: =(Reference!$B$2*Y12 + Reference!$B$3*AA12 + Reference!$B$4*Z12 + Reference!$B$5 * AB12)/4 -> 11.8125 | AD12: =IF(Q12=Reference!$C$41, Reference!$D$41, IF(Q12=Reference!$C$42, Reference!$D$42, IF(Q12=Reference!$C$43, Reference!$D$43, IF(Q12=Reference!$C$44, Reference!$D$44, 0)))) -> 10 | AE12: =1 + (AC12 * AD12) -> 119.125 | AF12: Raised by all six model outputs; medini T141 (PC5 + Uumodem | Denial of Service); copied from row 21 of the full analysis
A13: 12. Vehicle computer (signature verification and warning logic) | B13: Tampering | C13: Integrity | D13: Signature verification or the warning logic in the vehicle is modified so that unsigned or invalid DENMs are accepted, which makes every forged message effective even without stolen credentials. | E13: Physical or local access to the in-vehicle computing unit (debug port, unsigned software update) or compromise of the link between OBU and computer. | F13: Local | G13: The attacker needs direct access to the vehicle or to its internal network; the path is not reachable from the public network. | H13: Major | I13: The vehicle acts on forged warnings without any cryptographic barrier, which can provoke hard braking or wrong manoeuvres (S2). | J13: Moderate | K13: The scope is the individual vehicle rather than the deployment; warranty and liability costs. | L13: Major | M13: The verification function of the vehicle ITS station is lost. | N13: Negligible | O13: No personal data disclosure is involved. | P13: =IF(AC13>=Reference!$H$2, Reference!$G$2, IF(AC13>=Reference!$H$3, Reference!$G$3, IF(AC13>=Reference!$H$4, Reference!$G$4, IF(AC13>=Reference!$H$5, Reference!$G$5, "")))) -> Severe | Q13: =IF(F13="Physical", "Very Low", IF(F13="Local", "Low", IF(F13="Adjacent", "Medium", IF(F13="Network", "High", "")))) -> Low | R13: =IF(AE13>=Reference!$D$2, Reference!$E$2, IF(AE13>=Reference!$D$3, Reference!$E$3, IF(AE13>=Reference!$D$4, Reference!$E$4, IF(AE13>=Reference!$D$5, Reference!$E$5, "")))) -> Medium | S13: Mitigation | T13: Secure boot and signed software updates on the vehicle computer, disable debug interfaces in production, authenticate the link between OBU and computer, report verification failures to the back-end. | U13: OBU, in-vehicle computing unit (Steps 11-12), software update process. | V13: Per-vehicle scope and the local access requirement keep the risk lower, but the control is essential because it is the last line of defence. | W13: Integrity, Authenticity. | X13: T164 | Y13: =IF(H13=Reference!$A$12, Reference!$C$12, IF(H13=Reference!$A$11, Reference!$C$11, IF(H13=Reference!$A$10, Reference!$C$10, IF(H13=Reference!$A$9, Reference!$C$9, 0)))) -> 7 | Z13: =IF(J13=Reference!$A$20, Reference!$C$20, IF(J13=Reference!$A$19, Reference!$C$19, IF(J13=Reference!$A$18, Reference!$C$18, IF(J13=Reference!$A$17, Reference!$C$17, 0)))) -> 4 | AA13: =IF(L13=Reference!$A$28, Reference!$C$28, IF(L13=Reference!$A$27, Reference!$C$27, IF(L13=Reference!$A$26, Reference!$C$26, IF(L13=Reference!$A$25, Reference!$C$25, 0)))) -> 7 | AB13: =IF(N13=Reference!$A$36, Reference!$C$36, IF(N13=Reference!$A$35, Reference!$C$35, IF(N13=Reference!$A$34, Reference!$C$34, IF(N13=Reference!$A$33, Reference!$C$33, 0)))) -> 1 | AC13: =(Reference!$B$2*Y13 + Reference!$B$3*AA13 + Reference!$B$4*Z13 + Reference!$B$5 * AB13)/4 -> 11.0625 | AD13: =IF(Q13=Reference!$C$41, Reference!$D$41, IF(Q13=Reference!$C$42, Reference!$D$42, IF(Q13=Reference!$C$43, Reference!$D$43, IF(Q13=Reference!$C$44, Reference!$D$44, 0)))) -> 4 | AE13: =1 + (AC13 * AD13) -> 45.25 | AF13: Raised by all six model outputs; medini T164 (Verify, warning logic | Tampering); copied from row 7 of the full analysis
... A23: 10. Central ITS-S (operator console, PKI services) | B23: Elevation of privilege | C23: Authorization | D23: An attacker obtains administrative rights on the back-end and can issue or revoke certificates, push configuration to every roadside unit and publish or cancel warnings across the deployment. | E23: Compromise of an operator account, exploitation of the back-end application, or an insider with excessive rights. | F23: Network | G23: The console and the services are reachable over the network. | H23: Severe | I23: Control over every station and over the trust material can be used to fabricate or suppress warnings anywhere (S3). | J23: Severe | K23: Deployment-wide revocation, service interruption and regulatory consequences. | L23: Severe | M23: Every function of the deployment can be manipulated from one place. | N23: Major | O23: Operator and certificate records expose the identities of stations and vehicles. | P23: =IF(AC23>=Reference!$H$2, Reference!$G$2, IF(AC23>=Reference!$H$3, Reference!$G$3, IF(AC23>=Reference!$H$4, Reference!$G$4, IF(AC23>=Reference!$H$5, Reference!$G$5, "")))) -> Severe | Q23: =IF(F23="Physical", "Very Low", IF(F23="Local", "Low", IF(F23="Adjacent", "Medium", IF(F23="Network", "High", "")))) -> High | R23: =IF(AE23>=Reference!$D$2, Reference!$E$2, IF(AE23>=Reference!$D$3, Reference!$E$3, IF(AE23>=Reference!$D$4, Reference!$E$4, IF(AE23>=Reference!$D$5, Reference!$E$5, "")))) -> Critical | S23: Mitigation | T23: Multi-factor authentication and least privilege for operator accounts, separation of duties for certificate issuance, hardened and patched back-end, complete audit logging with alerting. | U23: Central ITS-S application and accounts, PKI services, RSU management interface (Step 10). | V23: Highest reach of the whole analysis, on a par with the certificate row. | W23: Authorization, Integrity, Availability. | X23: T209 | Y23: =IF(H23=Reference!$A$12, Reference!$C$12, IF(H23=Reference!$A$11, Reference!$C$11, IF(H23=Reference!$A$10, Reference!$C$10, IF(H23=Reference!$A$9, Reference!$C$9, 0)))) -> 10 | Z23: =IF(J23=Reference!$A$20, Reference!$C$20, IF(J23=Reference!$A$19, Reference!$C$19, IF(J23=Reference!$A$18, Reference!$C$18, IF(J23=Reference!$A$17, Reference!$C$17, 0)))) -> 10 | AA23: =IF(L23=Reference!$A$28, Reference!$C$28, IF(L23=Reference!$A$27, Reference!$C$27, IF(L23=Reference!$A$26, Reference!$C$26, IF(L23=Reference!$A$25, Reference!$C$25, 0)))) -> 10 | AB23: =IF(N23=Reference!$A$36, Reference!$C$36, IF(N23=Reference!$A$35, Reference!$C$35, IF(N23=Reference!$A$34, Reference!$C$34, IF(N23=Reference!$A$33, Reference!$C$33, 0)))) -> 7 | AC23: =(Reference!$B$2*Y23 + Reference!$B$3*AA23 + Reference!$B$4*Z23 + Reference!$B$5 * AB23)/4 -> 16.6875 | AD23: =IF(Q23=Reference!$C$41, Reference!$D$41, IF(Q23=Reference!$C$42, Reference!$D$42, IF(Q23=Reference!$C$43, Reference!$D$43, IF(Q23=Reference!$C$44, Reference!$D$44, 0)))) -> 10 | AE23: =1 + (AC23 * AD23) -> 167.875 | AF23: Raised by all six model outputs; medini T209 (PKI, operator | Elevation of Privilege); copied from row 33 of the full analysis

Sheet AI threat scenarios
A1: Asset | B1: Threat type | C1: Security Attribute | D1: Damage Scenario | E1: Attack Path | F1: Attack vector | G1: Attack Vector Note / Motiv | H1: Safety Impact | I1: Safety Note / Motiv | J1: Financial Impact | K1: Financial Note / Motiv | L1: Operational Impact | M1: Operational Note / Motiv | N1: Privacy and Legislative Impact | O1: Privacy Note / Motiv | P1: Severity Level | Q1: Feasibility Level | R1: Risk Value | S1: Treatment Options | T1: Measures | U1: Affected Design Elements | V1: Justification (Treatment) | W1: Cybersecurity Goals | X1: Medini threat ID | Y1: s | Z1: f | AA1: o | AB1: p | AC1: impact | AD1: feasibility val | AE1: Risk score | AF1: Theme, agreement and source
A2: 9. RSU (PC5 radio, signing keys in HSM) | B2: Spoofing | C2: Authenticity | D2: A rogue roadside device broadcasts DENMs that claim to originate from the legitimate RSU, announcing an accident that does not exist or cancelling a real one. Every vehicle in radio range shows a false hazard warning to the driver. | E2: The attacker operates a C-V2X radio inside the coverage area and either holds valid ITS credentials (stolen, extracted or issued to a rogue node) or exploits receivers that do not verify message signatures. | F2: Network | G2: The attack is carried out over the PC5 sidelink; no physical access to the roadside station is needed, only presence in the radio coverage area. | H2: Major | I2: A false accident warning at motorway speed can trigger hard braking and rear-end collisions; injuries are severe but survival is probable (S2). | J2: Major | K2: Liability claims after a provoked collision, incident response costs and possible suspension of the warning service in the affected area. | L2: Major | M2: The hazard warning function becomes untrustworthy and the operator may have to disable it locally until the source is identified. | N2: Negligible | O2: The forged message carries no personal data of road users. | P2: =IF(AC2>=Reference!$H$2, Reference!$G$2, IF(AC2>=Reference!$H$3, Reference!$G$3, IF(AC2>=Reference!$H$4, Reference!$G$4, IF(AC2>=Reference!$H$5, Reference!$G$5, "")))) -> Severe | Q2: =IF(F2="Physical", "Very Low", IF(F2="Local", "Low", IF(F2="Adjacent", "Medium", IF(F2="Network", "High", "")))) -> High | R2: =IF(AE2>=Reference!$D$2, Reference!$E$2, IF(AE2>=Reference!$D$3, Reference!$E$3, IF(AE2>=Reference!$D$4, Reference!$E$4, IF(AE2>=Reference!$D$5, Reference!$E$5, "")))) -> Critical | S2: Mitigation | T2: Verify IEEE 1609.2 / ETSI TS 103 097 signatures and certificate permissions in the OBU before a warning is displayed; plausibility and misbehaviour detection (position, cause code, event history); revocation of misbehaving certificates. | U2: RSU signing chain, OBU verification stack, PKI trust list, vehicle warning logic (Step 12). | V2: The scenario cannot be avoided, because receiving DENMs is the purpose of the function; mitigation through authentication and misbehaviour detection is the only practical option. | W2: Authenticity, Integrity, Non-repudiation. | X2: =IFERROR(INDEX(Mapping!$F$2:$F$44,MATCH(ROW(),Mapping!$A$2:$A$44,0)),"") -> T115 | Y2: =IF(H2=Reference!$A$12, Reference!$C$12, IF(H2=Reference!$A$11, Reference!$C$11, IF(H2=Reference!$A$10, Reference!$C$10, IF(H2=Reference!$A$9, Reference!$C$9, 0)))) -> 7 | Z2: =IF(J2=Reference!$A$20, Reference!$C$20, IF(J2=Reference!$A$19, Reference!$C$19, IF(J2=Reference!$A$18, Reference!$C$18, IF(J2=Reference!$A$17, Reference!$C$17, 0)))) -> 7 | AA2: =IF(L2=Reference!$A$28, Reference!$C$28, IF(L2=Reference!$A$27, Reference!$C$27, IF(L2=Reference!$A$26, Reference!$C$26, IF(L2=Reference!$A$25, Reference!$C$25, 0)))) -> 7 | AB2: =IF(N2=Reference!$A$36, Reference!$C$36, IF(N2=Reference!$A$35, Reference!$C$35, IF(N2=Reference!$A$34, Reference!$C$34, IF(N2=Reference!$A$33, Reference!$C$33, 0)))) -> 1 | AC2: =(Reference!$B$2*Y2 + Reference!$B$3*AA2 + Reference!$B$4*Z2 + Reference!$B$5 * AB2)/4 -> 11.4375 | AD2: =IF(Q2=Reference!$C$41, Reference!$D$41, IF(Q2=Reference!$C$42, Reference!$D$42, IF(Q2=Reference!$C$43, Reference!$D$43, IF(Q2=Reference!$C$44, Reference!$D$44, 0)))) -> 10 | AE2: =1 + (AC2 * AD2) -> 115.375 | AF2: Forged DENM or rogue RSU broadcast - 6/6 (consensus matrix)
A3: 8 -> 9. Link roadside computing unit to RSU (Ethernet/UDP) | B3: Spoofing | C3: Authenticity | D3: An attacker injects a forged DENM payload into the RSU input port. The RSU signs it with its legitimate key and broadcasts it, so receivers accept the false warning as authentic. | E3: The attacker gains a foothold in the roadside network, for example through the IP camera or an exposed maintenance port, and sends UDP packets to the RSU input port, which accepts any payload it receives. | F3: Adjacent | G3: The attack requires access to the roadside network segment; it cannot be executed from the public network. | H3: Major | I3: The effect equals a rogue RSU broadcast, but the message carries a valid signature, so on-board plausibility checks are the only remaining barrier (S2). | J3: Major | K3: Liability for a provoked collision and forensic effort to establish that the RSU itself was not compromised. | L3: Major | M3: All warnings from this roadside station must be treated as untrusted until the injection path is closed. | N3: Negligible | O3: No personal data is contained in the injected payload. | P3: =IF(AC3>=Reference!$H$2, Reference!$G$2, IF(AC3>=Reference!$H$3, Reference!$G$3, IF(AC3>=Reference!$H$4, Reference!$G$4, IF(AC3>=Reference!$H$5, Reference!$G$5, "")))) -> Severe | Q3: =IF(F3="Physical", "Very Low", IF(F3="Local", "Low", IF(F3="Adjacent", "Medium", IF(F3="Network", "High", "")))) -> Medium | R3: =IF(AE3>=Reference!$D$2, Reference!$E$2, IF(AE3>=Reference!$D$3, Reference!$E$3, IF(AE3>=Reference!$D$4, Reference!$E$4, IF(AE3>=Reference!$D$5, Reference!$E$5, "")))) -> High | S3: Mitigation | T3: Authenticate the source of payloads at the RSU input (mutual TLS or signed internal messages); restrict the port by ACL to the computing unit; segment the roadside LAN; log the origin of every signed payload. | U3: Roadside LAN, RSU input interface, computing unit (Steps 8-9), logging. | V3: The RSU signs whatever it receives, which turns a local network weakness into an authenticated false warning; source authentication removes the root cause. | W3: Authenticity, Integrity, Non-repudiation. | X3: =IFERROR(INDEX(Mapping!$F$2:$F$44,MATCH(ROW(),Mapping!$A$2:$A$44,0)),"") -> T110 | Y3: =IF(H3=Reference!$A$12, Reference!$C$12, IF(H3=Reference!$A$11, Reference!$C$11, IF(H3=Reference!$A$10, Reference!$C$10, IF(H3=Reference!$A$9, Reference!$C$9, 0)))) -> 7 | Z3: =IF(J3=Reference!$A$20, Reference!$C$20, IF(J3=Reference!$A$19, Reference!$C$19, IF(J3=Reference!$A$18, Reference!$C$18, IF(J3=Reference!$A$17, Reference!$C$17, 0)))) -> 7 | AA3: =IF(L3=Reference!$A$28, Reference!$C$28, IF(L3=Reference!$A$27, Reference!$C$27, IF(L3=Reference!$A$26, Reference!$C$26, IF(L3=Reference!$A$25, Reference!$C$25, 0)))) -> 7 | AB3: =IF(N3=Reference!$A$36, Reference!$C$36, IF(N3=Reference!$A$35, Reference!$C$35, IF(N3=Reference!$A$34, Reference!$C$34, IF(N3=Reference!$A$33, Reference!$C$33, 0)))) -> 1 | AC3: =(Reference!$B$2*Y3 + Reference!$B$3*AA3 + Reference!$B$4*Z3 + Reference!$B$5 * AB3)/4 -> 11.4375 | AD3: =IF(Q3=Reference!$C$41, Reference!$D$41, IF(Q3=Reference!$C$42, Reference!$D$42, IF(Q3=Reference!$C$43, Reference!$D$43, IF(Q3=Reference!$C$44, Reference!$D$44, 0)))) -> 7 | AE3: =1 + (AC3 * AD3) -> 81.0625 | AF3: Forged DENM or rogue RSU broadcast - 6/6; this attack path: 4/6 (ChatGPT, Sonnet 5, Opus 5 TS49, Copilot)
A4: 9. RSU (management interface, HSM) | B4: Elevation of privilege | C4: Authorization | D4: An attacker obtains administrative access to the RSU and uses the hardware security module as a signing oracle, producing an unlimited number of valid signed but fabricated DENMs, and can also suppress genuine ones. | E4: Exploitation of weak or default credentials, or of a vulnerability in the RSU management services reachable from the operator network. | F4: Network | G4: The management interface is reachable over the network, so no physical access is required. | H4: Severe | I4: The attacker controls what every vehicle in range is told, including suppression of a real accident warning, which can lead to life-threatening collisions (S3). | J4: Severe | K4: Fleet-wide loss of trust, certificate revocation campaign, regulatory consequences and liability for any resulting accident. | L4: Severe | M4: Complete loss of the warning function at the affected site, with the attacker in control of it. | N4: Moderate | O4: Administrative access exposes communication metadata and certificate information, but no direct personal data of road users. | P4: =IF(AC4>=Reference!$H$2, Reference!$G$2, IF(AC4>=Reference!$H$3, Reference!$G$3, IF(AC4>=Reference!$H$4, Reference!$G$4, IF(AC4>=Reference!$H$5, Reference!$G$5, "")))) -> Severe | Q4: =IF(F4="Physical", "Very Low", IF(F4="Local", "Low", IF(F4="Adjacent", "Medium", IF(F4="Network", "High", "")))) -> High | R4: =IF(AE4>=Reference!$D$2, Reference!$E$2, IF(AE4>=Reference!$D$3, Reference!$E$3, IF(AE4>=Reference!$D$4, Reference!$E$4, IF(AE4>=Reference!$D$5, Reference!$E$5, "")))) -> Critical | S4: Mitigation | T4: Remove default credentials, disable unused management services, restrict management access to a dedicated network, harden and update the firmware, bind HSM signing to authenticated request sources, monitor and log privileged operations. | U4: RSU firmware and management services, HSM key policy, operator network, logging. | V4: The highest-risk row of the theme, because it defeats both the signature check and the plausibility checks; standard hardening measures apply. | W4: Authenticity, Integrity, Availability, Non-repudiation. | X4: =IFERROR(INDEX(Mapping!$F$2:$F$44,MATCH(ROW(),Mapping!$A$2:$A$44,0)),"") -> T116 | Y4: =IF(H4=Reference!$A$12, Reference!$C$12, IF(H4=Reference!$A$11, Reference!$C$11, IF(H4=Reference!$A$10, Reference!$C$10, IF(H4=Reference!$A$9, Reference!$C$9, 0)))) -> 10 | Z4: =IF(J4=Reference!$A$20, Reference!$C$20, IF(J4=Reference!$A$19, Reference!$C$19, IF(J4=Reference!$A$18, Reference!$C$18, IF(J4=Reference!$A$17, Reference!$C$17, 0)))) -> 10 | AA4: =IF(L4=Reference!$A$28, Reference!$C$28, IF(L4=Reference!$A$27, Reference!$C$27, IF(L4=Reference!$A$26, Reference!$C$26, IF(L4=Reference!$A$25, Reference!$C$25, 0)))) -> 10 | AB4: =IF(N4=Reference!$A$36, Reference!$C$36, IF(N4=Reference!$A$35, Reference!$C$35, IF(N4=Reference!$A$34, Reference!$C$34, IF(N4=Reference!$A$33, Reference!$C$33, 0)))) -> 4 | AC4: =(Reference!$B$2*Y4 + Reference!$B$3*AA4 + Reference!$B$4*Z4 + Reference!$B$5 * AB4)/4 -> 16.5 | AD4: =IF(Q4=Reference!$C$41, Reference!$D$41, IF(Q4=Reference!$C$42, Reference!$D$42, IF(Q4=Reference!$C$43, Reference!$D$43, IF(Q4=Reference!$C$44, Reference!$D$44, 0)))) -> 10 | AE4: =1 + (AC4 * AD4) -> 166 | AF4: Forged DENM or rogue RSU broadcast - 6/6; this attack path: 5/6 (ChatGPT, Sonnet 5, Opus 5 TS58, Copilot, DeepSeek)
A5: 0. Security credentials and PKI (central ITS-S) | B5: Spoofing | C5: Authenticity | D5: Certificates are issued to, or stolen for, a rogue station, so its forged DENMs are accepted as genuine by every vehicle that trusts the PKI. | E5: Compromise of the authorization authority or of the operator console at the central ITS-S, or theft of enrolment credentials from a roadside unit. | F5: Network | G5: The PKI services and the operator console are reachable over the network. | H5: Severe | I5: Forged warnings can be produced anywhere in the deployment and are cryptographically valid, so on-board verification cannot reject them (S3). | J5: Severe | K5: Mass revocation and re-enrolment of stations, service interruption and regulatory reporting obligations. | L5: Severe | M5: The trust anchor of the whole C-ITS deployment is lost until certificates are reissued. | N5: Major | O5: Enrolment records and certificate metadata can link stations and vehicles to their operators. | P5: =IF(AC5>=Reference!$H$2, Reference!$G$2, IF(AC5>=Reference!$H$3, Reference!$G$3, IF(AC5>=Reference!$H$4, Reference!$G$4, IF(AC5>=Reference!$H$5, Reference!$G$5, "")))) -> Severe | Q5: =IF(F5="Physical", "Very Low", IF(F5="Local", "Low", IF(F5="Adjacent", "Medium", IF(F5="Network", "High", "")))) -> High | R5: =IF(AE5>=Reference!$D$2, Reference!$E$2, IF(AE5>=Reference!$D$3, Reference!$E$3, IF(AE5>=Reference!$D$4, Reference!$E$4, IF(AE5>=Reference!$D$5, Reference!$E$5, "")))) -> Critical | S5: Mitigation | T5: Protect CA keys in certified HSMs, separate enrolment and authorization authorities, issue short-lived authorization tickets, require multi-person approval and auditing for certificate issuance, monitor issuance anomalies, maintain a revocation process. | U5: Central ITS-S, PKI (enrolment and authorization authorities), trust list in RSU and OBU, credential storage. | V5: Low likelihood but the widest reach of all rows; the controls follow the C-ITS credential management requirements. | W5: Authenticity, Integrity, Non-repudiation. | X5: =IFERROR(INDEX(Mapping!$F$2:$F$44,MATCH(ROW(),Mapping!$A$2:$A$44,0)),"") -> T208 | Y5: =IF(H5=Reference!$A$12, Reference!$C$12, IF(H5=Reference!$A$11, Reference!$C$11, IF(H5=Reference!$A$10, Reference!$C$10, IF(H5=Reference!$A$9, Reference!$C$9, 0)))) -> 10 | Z5: =IF(J5=Reference!$A$20, Reference!$C$20, IF(J5=Reference!$A$19, Reference!$C$19, IF(J5=Reference!$A$18, Reference!$C$18, IF(J5=Reference!$A$17, Reference!$C$17, 0)))) -> 10 | AA5: =IF(L5=Reference!$A$28, Reference!$C$28, IF(L5=Reference!$A$27, Reference!$C$27, IF(L5=Reference!$A$26, Reference!$C$26, IF(L5=Reference!$A$25, Reference!$C$25, 0)))) -> 10 | AB5: =IF(N5=Reference!$A$36, Reference!$C$36, IF(N5=Reference!$A$35, Reference!$C$35, IF(N5=Reference!$A$34, Reference!$C$34, IF(N5=Reference!$A$33, Reference!$C$33, 0)))) -> 7 | AC5: =(Reference!$B$2*Y5 + Reference!$B$3*AA5 + Reference!$B$4*Z5 + Reference!$B$5 * AB5)/4 -> 16.6875 | AD5: =IF(Q5=Reference!$C$41, Reference!$D$41, IF(Q5=Reference!$C$42, Reference!$D$42, IF(Q5=Reference!$C$43, Reference!$D$43, IF(Q5=Reference!$C$44, Reference!$D$44, 0)))) -> 10 | AE5: =1 + (AC5 * AD5) -> 167.875 | AF5: PKI or CA compromise, rogue certificates - 6/6 (consensus matrix)
A6: 9. RSU signing keys (HSM) | B6: Information disclosure | C6: Confidentiality | D6: The private signing key of the RSU is extracted, for example because it is generated or stored outside the security module or through a physical side-channel attack, after which the attacker can sign forged DENMs indefinitely. | E6: Physical access to the pole-mounted RSU or to a decommissioned unit, combined with a misconfiguration that keeps key material outside the FIPS 140-2 level 3 module. | F6: Physical | G6: The attack path requires physical possession of, or direct access to, the roadside unit. | H6: Major | I6: The stolen key enables forged warnings with valid signatures; the effect equals a rogue RSU broadcast and persists until the certificate is revoked (S2). | J6: Major | K6: Revocation and replacement of the unit, investigation costs and liability if forged warnings were issued. | L6: Major | M6: Until revocation, every message signed with this key must be treated as untrusted. | N6: Negligible | O6: The key material itself exposes no personal data of road users. | P6: =IF(AC6>=Reference!$H$2, Reference!$G$2, IF(AC6>=Reference!$H$3, Reference!$G$3, IF(AC6>=Reference!$H$4, Reference!$G$4, IF(AC6>=Reference!$H$5, Reference!$G$5, "")))) -> Severe | Q6: =IF(F6="Physical", "Very Low", IF(F6="Local", "Low", IF(F6="Adjacent", "Medium", IF(F6="Network", "High", "")))) -> Very Low | R6: =IF(AE6>=Reference!$D$2, Reference!$E$2, IF(AE6>=Reference!$D$3, Reference!$E$3, IF(AE6>=Reference!$D$4, Reference!$E$4, IF(AE6>=Reference!$D$5, Reference!$E$5, "")))) -> Low | S6: Mitigation | T6: Generate and keep keys inside the HSM, enable tamper detection and zeroisation, physically secure the cabinet, monitor enclosure opening, revoke certificates as soon as tampering is detected. | U6: RSU hardware, HSM configuration, key management procedures, revocation service. | V6: Feasibility is low because physical access is required, which is why the risk value stays below the network-based rows even though the impact is comparable. | W6: Confidentiality, Authenticity, Integrity. | X6: =IFERROR(INDEX(Mapping!$F$2:$F$44,MATCH(ROW(),Mapping!$A$2:$A$44,0)),"") -> T112 | Y6: =IF(H6=Reference!$A$12, Reference!$C$12, IF(H6=Reference!$A$11, Reference!$C$11, IF(H6=Reference!$A$10, Reference!$C$10, IF(H6=Reference!$A$9, Reference!$C$9, 0)))) -> 7 | Z6: =IF(J6=Reference!$A$20, Reference!$C$20, IF(J6=Reference!$A$19, Reference!$C$19, IF(J6=Reference!$A$18, Reference!$C$18, IF(J6=Reference!$A$17, Reference!$C$17, 0)))) -> 7 | AA6: =IF(L6=Reference!$A$28, Reference!$C$28, IF(L6=Reference!$A$27, Reference!$C$27, IF(L6=Reference!$A$26, Reference!$C$26, IF(L6=Reference!$A$25, Reference!$C$25, 0)))) -> 7 | AB6: =IF(N6=Reference!$A$36, Reference!$C$36, IF(N6=Reference!$A$35, Reference!$C$35, IF(N6=Reference!$A$34, Reference!$C$34, IF(N6=Reference!$A$33, Reference!$C$33, 0)))) -> 1 | AC6: =(Reference!$B$2*Y6 + Reference!$B$3*AA6 + Reference!$B$4*Z6 + Reference!$B$5 * AB6)/4 -> 11.4375 | AD6: =IF(Q6=Reference!$C$41, Reference!$D$41, IF(Q6=Reference!$C$42, Reference!$D$42, IF(Q6=Reference!$C$43, Reference!$D$43, IF(Q6=Reference!$C$44, Reference!$D$44, 0)))) -> 1 | AE6: =1 + (AC6 * AD6) -> 12.4375 | AF6: Signing key or credential theft (HSM, PKI) - 6/6 (consensus matrix)
